[2024-08-17T14:44:28.368+0000] {local_task_job_runner.py:120} INFO - ::group::Pre task execution logs
[2024-08-17T14:44:28.549+0000] {taskinstance.py:2076} INFO - Dependencies all met for dep_context=non-requeueable deps ti=<TaskInstance: weather_etl_dag.send_email_with_csv scheduled__2024-08-15T00:00:00+00:00 [queued]>
[2024-08-17T14:44:28.559+0000] {taskinstance.py:2076} INFO - Dependencies all met for dep_context=requeueable deps ti=<TaskInstance: weather_etl_dag.send_email_with_csv scheduled__2024-08-15T00:00:00+00:00 [queued]>
[2024-08-17T14:44:28.577+0000] {taskinstance.py:2306} INFO - Starting attempt 1 of 2
[2024-08-17T14:44:28.734+0000] {taskinstance.py:2330} INFO - Executing <Task(PythonOperator): send_email_with_csv> on 2024-08-15 00:00:00+00:00
[2024-08-17T14:44:28.740+0000] {warnings.py:112} WARNING - /home/***/.local/lib/python3.12/site-packages/***/task/task_runner/standard_task_runner.py:62: DeprecationWarning: This process (pid=584) is multi-threaded, use of fork() may lead to deadlocks in the child.
  pid = os.fork()

[2024-08-17T14:44:28.743+0000] {standard_task_runner.py:64} INFO - Started process 586 to run task
[2024-08-17T14:44:28.743+0000] {standard_task_runner.py:90} INFO - Running: ['***', 'tasks', 'run', 'weather_etl_dag', 'send_email_with_csv', 'scheduled__2024-08-15T00:00:00+00:00', '--job-id', '182', '--raw', '--subdir', 'DAGS_FOLDER/weather_etl_dag.py', '--cfg-path', '/tmp/tmpfuvo50_y']
[2024-08-17T14:44:28.746+0000] {standard_task_runner.py:91} INFO - Job 182: Subtask send_email_with_csv
[2024-08-17T14:44:28.923+0000] {task_command.py:426} INFO - Running <TaskInstance: weather_etl_dag.send_email_with_csv scheduled__2024-08-15T00:00:00+00:00 [running]> on host 40ce90ebbdd9
[2024-08-17T14:44:29.310+0000] {taskinstance.py:2648} INFO - Exporting env vars: AIRFLOW_CTX_DAG_OWNER='***' AIRFLOW_CTX_DAG_ID='weather_etl_dag' AIRFLOW_CTX_TASK_ID='send_email_with_csv' AIRFLOW_CTX_EXECUTION_DATE='2024-08-15T00:00:00+00:00' AIRFLOW_CTX_TRY_NUMBER='1' AIRFLOW_CTX_DAG_RUN_ID='scheduled__2024-08-15T00:00:00+00:00'
[2024-08-17T14:44:29.313+0000] {taskinstance.py:430} INFO - ::endgroup::
[2024-08-17T14:44:29.347+0000] {taskinstance.py:441} INFO - ::group::Post task execution logs
[2024-08-17T14:44:29.350+0000] {taskinstance.py:2905} ERROR - Task failed with exception
Traceback (most recent call last):
  File "/home/airflow/.local/lib/python3.12/site-packages/airflow/models/taskinstance.py", line 465, in _execute_task
    result = _execute_callable(context=context, **execute_callable_kwargs)
             ^^^^^^^^^^^^^^^^^^^^^^^^^^^^^^^^^^^^^^^^^^^^^^^^^^^^^^^^^^^^^
  File "/home/airflow/.local/lib/python3.12/site-packages/airflow/models/taskinstance.py", line 432, in _execute_callable
    return execute_callable(context=context, **execute_callable_kwargs)
           ^^^^^^^^^^^^^^^^^^^^^^^^^^^^^^^^^^^^^^^^^^^^^^^^^^^^^^^^^^^^
  File "/home/airflow/.local/lib/python3.12/site-packages/airflow/models/baseoperator.py", line 401, in wrapper
    return func(self, *args, **kwargs)
           ^^^^^^^^^^^^^^^^^^^^^^^^^^^
  File "/home/airflow/.local/lib/python3.12/site-packages/airflow/operators/python.py", line 235, in execute
    return_value = self.execute_callable()
                   ^^^^^^^^^^^^^^^^^^^^^^^
  File "/home/airflow/.local/lib/python3.12/site-packages/airflow/operators/python.py", line 252, in execute_callable
    return self.python_callable(*self.op_args, **self.op_kwargs)
           ^^^^^^^^^^^^^^^^^^^^^^^^^^^^^^^^^^^^^^^^^^^^^^^^^^^^^
  File "/opt/airflow/dags/weather_etl_dag.py", line 435, in send_email_with_csv
    smtp_user = Variable.get("from_email")  # Correo de Gmail
                ^^^^^^^^^^^^^^^^^^^^^^^^^^
  File "/home/airflow/.local/lib/python3.12/site-packages/airflow/models/variable.py", line 143, in get
    raise KeyError(f"Variable {key} does not exist")
KeyError: 'Variable from_email does not exist'
[2024-08-17T14:44:29.370+0000] {taskinstance.py:1206} INFO - Marking task as UP_FOR_RETRY. dag_id=weather_etl_dag, task_id=send_email_with_csv, run_id=scheduled__2024-08-15T00:00:00+00:00, execution_date=20240815T000000, start_date=20240817T144428, end_date=20240817T144429
[2024-08-17T14:44:29.483+0000] {standard_task_runner.py:110} ERROR - Failed to execute job 182 for task send_email_with_csv ('Variable from_email does not exist'; 586)
[2024-08-17T14:44:29.520+0000] {local_task_job_runner.py:243} INFO - Task exited with return code 1
[2024-08-17T14:44:29.541+0000] {taskinstance.py:3503} INFO - 0 downstream tasks scheduled from follow-on schedule check
[2024-08-17T14:44:29.588+0000] {local_task_job_runner.py:222} INFO - ::endgroup::
