[2024-08-14T04:40:09.931+0000] {local_task_job_runner.py:120} INFO - ::group::Pre task execution logs
[2024-08-14T04:40:10.219+0000] {taskinstance.py:2076} INFO - Dependencies all met for dep_context=non-requeueable deps ti=<TaskInstance: weather_etl_dag.send_email_with_csv manual__2024-08-14T04:36:52.022202+00:00 [queued]>
[2024-08-14T04:40:10.232+0000] {taskinstance.py:2076} INFO - Dependencies all met for dep_context=requeueable deps ti=<TaskInstance: weather_etl_dag.send_email_with_csv manual__2024-08-14T04:36:52.022202+00:00 [queued]>
[2024-08-14T04:40:10.239+0000] {taskinstance.py:2306} INFO - Starting attempt 1 of 2
[2024-08-14T04:40:10.305+0000] {taskinstance.py:2330} INFO - Executing <Task(PythonOperator): send_email_with_csv> on 2024-08-14 04:36:52.022202+00:00
[2024-08-14T04:40:10.311+0000] {warnings.py:112} WARNING - /home/***/.local/lib/python3.12/site-packages/***/task/task_runner/standard_task_runner.py:62: DeprecationWarning: This process (pid=3242) is multi-threaded, use of fork() may lead to deadlocks in the child.
  pid = os.fork()

[2024-08-14T04:40:10.313+0000] {standard_task_runner.py:64} INFO - Started process 3245 to run task
[2024-08-14T04:40:10.318+0000] {standard_task_runner.py:90} INFO - Running: ['***', 'tasks', 'run', 'weather_etl_dag', 'send_email_with_csv', 'manual__2024-08-14T04:36:52.022202+00:00', '--job-id', '100', '--raw', '--subdir', 'DAGS_FOLDER/weather_etl_dag.py', '--cfg-path', '/tmp/tmpo4zekbfh']
[2024-08-14T04:40:10.321+0000] {standard_task_runner.py:91} INFO - Job 100: Subtask send_email_with_csv
[2024-08-14T04:40:10.412+0000] {task_command.py:426} INFO - Running <TaskInstance: weather_etl_dag.send_email_with_csv manual__2024-08-14T04:36:52.022202+00:00 [running]> on host 712d18ef94ea
[2024-08-14T04:40:10.710+0000] {taskinstance.py:2648} INFO - Exporting env vars: AIRFLOW_CTX_DAG_OWNER='***' AIRFLOW_CTX_DAG_ID='weather_etl_dag' AIRFLOW_CTX_TASK_ID='send_email_with_csv' AIRFLOW_CTX_EXECUTION_DATE='2024-08-14T04:36:52.022202+00:00' AIRFLOW_CTX_TRY_NUMBER='1' AIRFLOW_CTX_DAG_RUN_ID='manual__2024-08-14T04:36:52.022202+00:00'
[2024-08-14T04:40:10.711+0000] {taskinstance.py:430} INFO - ::endgroup::
[2024-08-14T04:40:11.430+0000] {warnings.py:112} WARNING - /opt/***/dags/weather_etl_dag.py:437: UserWarning: pandas only supports SQLAlchemy connectable (engine/connection) or database string URI or sqlite3 DBAPI2 connection. Other DBAPI2 objects are not tested. Please consider using SQLAlchemy.
  df_pronosticos = pd.read_sql_query(query, conn)

[2024-08-14T04:40:11.917+0000] {logging_mixin.py:188} INFO - Pronósticos obtenidos: 0 registros
[2024-08-14T04:40:13.161+0000] {logging_mixin.py:188} INFO - Fallo en el envío del correo: (535, b'5.7.8 Username and Password not accepted. For more information, go to\n5.7.8  https://support.google.com/mail/?p=BadCredentials 46e09a7af769-70c7b8288ffsm2109906a34.32 - gsmtp')
[2024-08-14T04:40:13.168+0000] {python.py:237} INFO - Done. Returned value was: None
[2024-08-14T04:40:13.169+0000] {taskinstance.py:441} INFO - ::group::Post task execution logs
[2024-08-14T04:40:13.193+0000] {taskinstance.py:1206} INFO - Marking task as SUCCESS. dag_id=weather_etl_dag, task_id=send_email_with_csv, run_id=manual__2024-08-14T04:36:52.022202+00:00, execution_date=20240814T043652, start_date=20240814T044010, end_date=20240814T044013
[2024-08-14T04:40:13.328+0000] {local_task_job_runner.py:243} INFO - Task exited with return code 0
[2024-08-14T04:40:13.366+0000] {taskinstance.py:3503} INFO - 0 downstream tasks scheduled from follow-on schedule check
[2024-08-14T04:40:13.472+0000] {local_task_job_runner.py:222} INFO - ::endgroup::
