[2024-08-31T14:57:55.201+0000] {processor.py:161} INFO - Started process (PID=63) to work on /opt/airflow/dags/weather_etl_dag.py
[2024-08-31T14:57:55.216+0000] {processor.py:830} INFO - Processing file /opt/airflow/dags/weather_etl_dag.py for tasks to queue
[2024-08-31T14:57:55.226+0000] {logging_mixin.py:188} INFO - [2024-08-31T14:57:55.226+0000] {dagbag.py:545} INFO - Filling up the DagBag from /opt/airflow/dags/weather_etl_dag.py
[2024-08-31T14:58:12.569+0000] {logging_mixin.py:188} INFO - [2024-08-31T14:58:12.564+0000] {dagbag.py:355} ERROR - Failed to import: /opt/airflow/dags/weather_etl_dag.py
Traceback (most recent call last):
  File "/home/airflow/.local/lib/python3.12/site-packages/airflow/models/dagbag.py", line 351, in parse
    loader.exec_module(new_module)
  File "<frozen importlib._bootstrap_external>", line 995, in exec_module
  File "<frozen importlib._bootstrap>", line 488, in _call_with_frames_removed
  File "/opt/airflow/dags/weather_etl_dag.py", line 5, in <module>
    from weather_etl import install_packages, get_municipios, fetch_weather_data, translate_and_clean_data
  File "/opt/airflow/dags/weather_etl.py", line 5, in <module>
    from translate import Translator
ModuleNotFoundError: No module named 'translate'
[2024-08-31T14:58:12.572+0000] {processor.py:842} WARNING - No viable dags retrieved from /opt/airflow/dags/weather_etl_dag.py
[2024-08-31T14:58:12.646+0000] {processor.py:183} INFO - Processing /opt/airflow/dags/weather_etl_dag.py took 17.453 seconds
[2024-08-31T15:08:13.113+0000] {processor.py:161} INFO - Started process (PID=186) to work on /opt/airflow/dags/weather_etl_dag.py
[2024-08-31T15:08:13.114+0000] {processor.py:830} INFO - Processing file /opt/airflow/dags/weather_etl_dag.py for tasks to queue
[2024-08-31T15:08:13.116+0000] {logging_mixin.py:188} INFO - [2024-08-31T15:08:13.115+0000] {dagbag.py:545} INFO - Filling up the DagBag from /opt/airflow/dags/weather_etl_dag.py
[2024-08-31T15:08:13.412+0000] {logging_mixin.py:188} INFO - [2024-08-31T15:08:13.407+0000] {dagbag.py:355} ERROR - Failed to import: /opt/airflow/dags/weather_etl_dag.py
Traceback (most recent call last):
  File "/home/airflow/.local/lib/python3.12/site-packages/airflow/models/dagbag.py", line 351, in parse
    loader.exec_module(new_module)
  File "<frozen importlib._bootstrap_external>", line 995, in exec_module
  File "<frozen importlib._bootstrap>", line 488, in _call_with_frames_removed
  File "/opt/airflow/dags/weather_etl_dag.py", line 5, in <module>
    from weather_etl import install_packages, get_municipios, fetch_weather_data, translate_and_clean_data
  File "/opt/airflow/dags/weather_etl.py", line 5, in <module>
    from translate import Translator
ModuleNotFoundError: No module named 'translate'
[2024-08-31T15:08:13.414+0000] {processor.py:842} WARNING - No viable dags retrieved from /opt/airflow/dags/weather_etl_dag.py
[2024-08-31T15:08:13.468+0000] {processor.py:183} INFO - Processing /opt/airflow/dags/weather_etl_dag.py took 0.359 seconds
[2024-08-31T15:18:14.296+0000] {processor.py:161} INFO - Started process (PID=309) to work on /opt/airflow/dags/weather_etl_dag.py
[2024-08-31T15:18:14.297+0000] {processor.py:830} INFO - Processing file /opt/airflow/dags/weather_etl_dag.py for tasks to queue
[2024-08-31T15:18:14.298+0000] {logging_mixin.py:188} INFO - [2024-08-31T15:18:14.298+0000] {dagbag.py:545} INFO - Filling up the DagBag from /opt/airflow/dags/weather_etl_dag.py
[2024-08-31T15:18:14.696+0000] {logging_mixin.py:188} INFO - [2024-08-31T15:18:14.692+0000] {dagbag.py:355} ERROR - Failed to import: /opt/airflow/dags/weather_etl_dag.py
Traceback (most recent call last):
  File "/home/airflow/.local/lib/python3.12/site-packages/airflow/models/dagbag.py", line 351, in parse
    loader.exec_module(new_module)
  File "<frozen importlib._bootstrap_external>", line 995, in exec_module
  File "<frozen importlib._bootstrap>", line 488, in _call_with_frames_removed
  File "/opt/airflow/dags/weather_etl_dag.py", line 5, in <module>
    from weather_etl import install_packages, get_municipios, fetch_weather_data, translate_and_clean_data
  File "/opt/airflow/dags/weather_etl.py", line 5, in <module>
    from translate import Translator
ModuleNotFoundError: No module named 'translate'
[2024-08-31T15:18:14.698+0000] {processor.py:842} WARNING - No viable dags retrieved from /opt/airflow/dags/weather_etl_dag.py
[2024-08-31T15:18:14.740+0000] {processor.py:183} INFO - Processing /opt/airflow/dags/weather_etl_dag.py took 0.449 seconds
[2024-08-31T15:28:15.124+0000] {processor.py:161} INFO - Started process (PID=434) to work on /opt/airflow/dags/weather_etl_dag.py
[2024-08-31T15:28:15.125+0000] {processor.py:830} INFO - Processing file /opt/airflow/dags/weather_etl_dag.py for tasks to queue
[2024-08-31T15:28:15.126+0000] {logging_mixin.py:188} INFO - [2024-08-31T15:28:15.126+0000] {dagbag.py:545} INFO - Filling up the DagBag from /opt/airflow/dags/weather_etl_dag.py
[2024-08-31T15:28:15.515+0000] {logging_mixin.py:188} INFO - [2024-08-31T15:28:15.511+0000] {dagbag.py:355} ERROR - Failed to import: /opt/airflow/dags/weather_etl_dag.py
Traceback (most recent call last):
  File "/home/airflow/.local/lib/python3.12/site-packages/airflow/models/dagbag.py", line 351, in parse
    loader.exec_module(new_module)
  File "<frozen importlib._bootstrap_external>", line 995, in exec_module
  File "<frozen importlib._bootstrap>", line 488, in _call_with_frames_removed
  File "/opt/airflow/dags/weather_etl_dag.py", line 5, in <module>
    from weather_etl import install_packages, get_municipios, fetch_weather_data, translate_and_clean_data
  File "/opt/airflow/dags/weather_etl.py", line 5, in <module>
    from translate import Translator
ModuleNotFoundError: No module named 'translate'
[2024-08-31T15:28:15.517+0000] {processor.py:842} WARNING - No viable dags retrieved from /opt/airflow/dags/weather_etl_dag.py
[2024-08-31T15:28:15.570+0000] {processor.py:183} INFO - Processing /opt/airflow/dags/weather_etl_dag.py took 0.450 seconds
[2024-08-31T15:38:16.306+0000] {processor.py:161} INFO - Started process (PID=560) to work on /opt/airflow/dags/weather_etl_dag.py
[2024-08-31T15:38:16.307+0000] {processor.py:830} INFO - Processing file /opt/airflow/dags/weather_etl_dag.py for tasks to queue
[2024-08-31T15:38:16.308+0000] {logging_mixin.py:188} INFO - [2024-08-31T15:38:16.308+0000] {dagbag.py:545} INFO - Filling up the DagBag from /opt/airflow/dags/weather_etl_dag.py
[2024-08-31T15:38:16.765+0000] {logging_mixin.py:188} INFO - [2024-08-31T15:38:16.759+0000] {dagbag.py:355} ERROR - Failed to import: /opt/airflow/dags/weather_etl_dag.py
Traceback (most recent call last):
  File "/home/airflow/.local/lib/python3.12/site-packages/airflow/models/dagbag.py", line 351, in parse
    loader.exec_module(new_module)
  File "<frozen importlib._bootstrap_external>", line 995, in exec_module
  File "<frozen importlib._bootstrap>", line 488, in _call_with_frames_removed
  File "/opt/airflow/dags/weather_etl_dag.py", line 5, in <module>
    from weather_etl import install_packages, get_municipios, fetch_weather_data, translate_and_clean_data
  File "/opt/airflow/dags/weather_etl.py", line 5, in <module>
    from translate import Translator
ModuleNotFoundError: No module named 'translate'
[2024-08-31T15:38:16.766+0000] {processor.py:842} WARNING - No viable dags retrieved from /opt/airflow/dags/weather_etl_dag.py
[2024-08-31T15:38:16.895+0000] {processor.py:183} INFO - Processing /opt/airflow/dags/weather_etl_dag.py took 0.594 seconds
[2024-08-31T16:00:00.106+0000] {processor.py:161} INFO - Started process (PID=63) to work on /opt/airflow/dags/weather_etl_dag.py
[2024-08-31T16:00:00.116+0000] {processor.py:830} INFO - Processing file /opt/airflow/dags/weather_etl_dag.py for tasks to queue
[2024-08-31T16:00:00.119+0000] {logging_mixin.py:188} INFO - [2024-08-31T16:00:00.118+0000] {dagbag.py:545} INFO - Filling up the DagBag from /opt/airflow/dags/weather_etl_dag.py
[2024-08-31T16:00:20.221+0000] {logging_mixin.py:188} INFO - [2024-08-31T16:00:20.215+0000] {dagbag.py:355} ERROR - Failed to import: /opt/airflow/dags/weather_etl_dag.py
Traceback (most recent call last):
  File "/home/airflow/.local/lib/python3.12/site-packages/airflow/models/dagbag.py", line 351, in parse
    loader.exec_module(new_module)
  File "<frozen importlib._bootstrap_external>", line 995, in exec_module
  File "<frozen importlib._bootstrap>", line 488, in _call_with_frames_removed
  File "/opt/airflow/dags/weather_etl_dag.py", line 5, in <module>
    from weather_etl import install_packages, get_municipios, fetch_weather_data, translate_and_clean_data
  File "/opt/airflow/dags/weather_etl.py", line 5, in <module>
    from translate import Translator
ModuleNotFoundError: No module named 'translate'
[2024-08-31T16:00:20.223+0000] {processor.py:842} WARNING - No viable dags retrieved from /opt/airflow/dags/weather_etl_dag.py
[2024-08-31T16:00:20.288+0000] {processor.py:183} INFO - Processing /opt/airflow/dags/weather_etl_dag.py took 20.254 seconds
[2024-08-31T16:01:03.928+0000] {processor.py:161} INFO - Started process (PID=54) to work on /opt/airflow/dags/weather_etl_dag.py
[2024-08-31T16:01:03.929+0000] {processor.py:830} INFO - Processing file /opt/airflow/dags/weather_etl_dag.py for tasks to queue
[2024-08-31T16:01:03.931+0000] {logging_mixin.py:188} INFO - [2024-08-31T16:01:03.931+0000] {dagbag.py:545} INFO - Filling up the DagBag from /opt/airflow/dags/weather_etl_dag.py
[2024-08-31T16:01:04.262+0000] {logging_mixin.py:188} INFO - [2024-08-31T16:01:04.257+0000] {dagbag.py:355} ERROR - Failed to import: /opt/airflow/dags/weather_etl_dag.py
Traceback (most recent call last):
  File "/home/airflow/.local/lib/python3.12/site-packages/airflow/models/dagbag.py", line 351, in parse
    loader.exec_module(new_module)
  File "<frozen importlib._bootstrap_external>", line 995, in exec_module
  File "<frozen importlib._bootstrap>", line 488, in _call_with_frames_removed
  File "/opt/airflow/dags/weather_etl_dag.py", line 5, in <module>
    from weather_etl import install_packages, get_municipios, fetch_weather_data, translate_and_clean_data
  File "/opt/airflow/dags/weather_etl.py", line 5, in <module>
    from translate import Translator
ModuleNotFoundError: No module named 'translate'
[2024-08-31T16:01:04.264+0000] {processor.py:842} WARNING - No viable dags retrieved from /opt/airflow/dags/weather_etl_dag.py
[2024-08-31T16:01:04.341+0000] {processor.py:183} INFO - Processing /opt/airflow/dags/weather_etl_dag.py took 0.419 seconds
[2024-08-31T16:11:04.968+0000] {processor.py:161} INFO - Started process (PID=174) to work on /opt/airflow/dags/weather_etl_dag.py
[2024-08-31T16:11:04.969+0000] {processor.py:830} INFO - Processing file /opt/airflow/dags/weather_etl_dag.py for tasks to queue
[2024-08-31T16:11:04.970+0000] {logging_mixin.py:188} INFO - [2024-08-31T16:11:04.970+0000] {dagbag.py:545} INFO - Filling up the DagBag from /opt/airflow/dags/weather_etl_dag.py
[2024-08-31T16:11:05.347+0000] {logging_mixin.py:188} INFO - [2024-08-31T16:11:05.342+0000] {dagbag.py:355} ERROR - Failed to import: /opt/airflow/dags/weather_etl_dag.py
Traceback (most recent call last):
  File "/home/airflow/.local/lib/python3.12/site-packages/airflow/models/dagbag.py", line 351, in parse
    loader.exec_module(new_module)
  File "<frozen importlib._bootstrap_external>", line 995, in exec_module
  File "<frozen importlib._bootstrap>", line 488, in _call_with_frames_removed
  File "/opt/airflow/dags/weather_etl_dag.py", line 5, in <module>
    from weather_etl import install_packages, get_municipios, fetch_weather_data, translate_and_clean_data
  File "/opt/airflow/dags/weather_etl.py", line 5, in <module>
    from translate import Translator
ModuleNotFoundError: No module named 'translate'
[2024-08-31T16:11:05.348+0000] {processor.py:842} WARNING - No viable dags retrieved from /opt/airflow/dags/weather_etl_dag.py
[2024-08-31T16:11:05.400+0000] {processor.py:183} INFO - Processing /opt/airflow/dags/weather_etl_dag.py took 0.437 seconds
[2024-08-31T16:21:05.930+0000] {processor.py:161} INFO - Started process (PID=298) to work on /opt/airflow/dags/weather_etl_dag.py
[2024-08-31T16:21:05.931+0000] {processor.py:830} INFO - Processing file /opt/airflow/dags/weather_etl_dag.py for tasks to queue
[2024-08-31T16:21:05.934+0000] {logging_mixin.py:188} INFO - [2024-08-31T16:21:05.934+0000] {dagbag.py:545} INFO - Filling up the DagBag from /opt/airflow/dags/weather_etl_dag.py
[2024-08-31T16:21:06.618+0000] {logging_mixin.py:188} INFO - [2024-08-31T16:21:06.613+0000] {dagbag.py:355} ERROR - Failed to import: /opt/airflow/dags/weather_etl_dag.py
Traceback (most recent call last):
  File "/home/airflow/.local/lib/python3.12/site-packages/airflow/models/dagbag.py", line 351, in parse
    loader.exec_module(new_module)
  File "<frozen importlib._bootstrap_external>", line 995, in exec_module
  File "<frozen importlib._bootstrap>", line 488, in _call_with_frames_removed
  File "/opt/airflow/dags/weather_etl_dag.py", line 5, in <module>
    from weather_etl import install_packages, get_municipios, fetch_weather_data, translate_and_clean_data
  File "/opt/airflow/dags/weather_etl.py", line 5, in <module>
    from translate import Translator
ModuleNotFoundError: No module named 'translate'
[2024-08-31T16:21:06.620+0000] {processor.py:842} WARNING - No viable dags retrieved from /opt/airflow/dags/weather_etl_dag.py
[2024-08-31T16:21:06.675+0000] {processor.py:183} INFO - Processing /opt/airflow/dags/weather_etl_dag.py took 0.753 seconds
[2024-08-31T16:27:19.400+0000] {processor.py:161} INFO - Started process (PID=64) to work on /opt/airflow/dags/weather_etl_dag.py
[2024-08-31T16:27:19.406+0000] {processor.py:830} INFO - Processing file /opt/airflow/dags/weather_etl_dag.py for tasks to queue
[2024-08-31T16:27:19.438+0000] {logging_mixin.py:188} INFO - [2024-08-31T16:27:19.423+0000] {dagbag.py:545} INFO - Filling up the DagBag from /opt/airflow/dags/weather_etl_dag.py
[2024-08-31T16:27:23.646+0000] {logging_mixin.py:188} INFO - [2024-08-31T16:27:23.633+0000] {dagbag.py:355} ERROR - Failed to import: /opt/airflow/dags/weather_etl_dag.py
Traceback (most recent call last):
  File "/home/airflow/.local/lib/python3.12/site-packages/airflow/models/dagbag.py", line 351, in parse
    loader.exec_module(new_module)
  File "<frozen importlib._bootstrap_external>", line 995, in exec_module
  File "<frozen importlib._bootstrap>", line 488, in _call_with_frames_removed
  File "/opt/airflow/dags/weather_etl_dag.py", line 5, in <module>
    from weather_etl import install_packages, get_municipios, fetch_weather_data, translate_and_clean_data
  File "/opt/airflow/dags/weather_etl.py", line 5, in <module>
    from translate import Translator
ModuleNotFoundError: No module named 'translate'
[2024-08-31T16:27:23.648+0000] {processor.py:842} WARNING - No viable dags retrieved from /opt/airflow/dags/weather_etl_dag.py
[2024-08-31T16:27:23.725+0000] {processor.py:183} INFO - Processing /opt/airflow/dags/weather_etl_dag.py took 4.331 seconds
[2024-08-31T16:37:24.152+0000] {processor.py:161} INFO - Started process (PID=186) to work on /opt/airflow/dags/weather_etl_dag.py
[2024-08-31T16:37:24.153+0000] {processor.py:830} INFO - Processing file /opt/airflow/dags/weather_etl_dag.py for tasks to queue
[2024-08-31T16:37:24.156+0000] {logging_mixin.py:188} INFO - [2024-08-31T16:37:24.155+0000] {dagbag.py:545} INFO - Filling up the DagBag from /opt/airflow/dags/weather_etl_dag.py
[2024-08-31T16:37:25.241+0000] {logging_mixin.py:188} INFO - [2024-08-31T16:37:25.235+0000] {dagbag.py:355} ERROR - Failed to import: /opt/airflow/dags/weather_etl_dag.py
Traceback (most recent call last):
  File "/home/airflow/.local/lib/python3.12/site-packages/airflow/models/dagbag.py", line 351, in parse
    loader.exec_module(new_module)
  File "<frozen importlib._bootstrap_external>", line 995, in exec_module
  File "<frozen importlib._bootstrap>", line 488, in _call_with_frames_removed
  File "/opt/airflow/dags/weather_etl_dag.py", line 5, in <module>
    from weather_etl import install_packages, get_municipios, fetch_weather_data, translate_and_clean_data
  File "/opt/airflow/dags/weather_etl.py", line 5, in <module>
    from translate import Translator
ModuleNotFoundError: No module named 'translate'
[2024-08-31T16:37:25.243+0000] {processor.py:842} WARNING - No viable dags retrieved from /opt/airflow/dags/weather_etl_dag.py
[2024-08-31T16:37:25.305+0000] {processor.py:183} INFO - Processing /opt/airflow/dags/weather_etl_dag.py took 1.162 seconds
[2024-08-31T16:57:48.358+0000] {processor.py:161} INFO - Started process (PID=65) to work on /opt/airflow/dags/weather_etl_dag.py
[2024-08-31T16:57:48.393+0000] {processor.py:830} INFO - Processing file /opt/airflow/dags/weather_etl_dag.py for tasks to queue
[2024-08-31T16:57:48.396+0000] {logging_mixin.py:188} INFO - [2024-08-31T16:57:48.395+0000] {dagbag.py:545} INFO - Filling up the DagBag from /opt/airflow/dags/weather_etl_dag.py
[2024-08-31T16:57:54.537+0000] {logging_mixin.py:188} INFO - [2024-08-31T16:57:54.532+0000] {dagbag.py:355} ERROR - Failed to import: /opt/airflow/dags/weather_etl_dag.py
Traceback (most recent call last):
  File "/home/airflow/.local/lib/python3.12/site-packages/airflow/models/dagbag.py", line 351, in parse
    loader.exec_module(new_module)
  File "<frozen importlib._bootstrap_external>", line 995, in exec_module
  File "<frozen importlib._bootstrap>", line 488, in _call_with_frames_removed
  File "/opt/airflow/dags/weather_etl_dag.py", line 5, in <module>
    from weather_etl import install_packages, get_municipios, fetch_weather_data, translate_and_clean_data
  File "/opt/airflow/dags/weather_etl.py", line 5, in <module>
    from translate import Translator
ModuleNotFoundError: No module named 'translate'
[2024-08-31T16:57:54.539+0000] {processor.py:842} WARNING - No viable dags retrieved from /opt/airflow/dags/weather_etl_dag.py
[2024-08-31T16:57:54.613+0000] {processor.py:183} INFO - Processing /opt/airflow/dags/weather_etl_dag.py took 6.279 seconds
[2024-08-31T17:33:41.974+0000] {processor.py:161} INFO - Started process (PID=63) to work on /opt/airflow/dags/weather_etl_dag.py
[2024-08-31T17:33:41.976+0000] {processor.py:830} INFO - Processing file /opt/airflow/dags/weather_etl_dag.py for tasks to queue
[2024-08-31T17:33:41.984+0000] {logging_mixin.py:188} INFO - [2024-08-31T17:33:41.984+0000] {dagbag.py:545} INFO - Filling up the DagBag from /opt/airflow/dags/weather_etl_dag.py
[2024-08-31T17:34:00.882+0000] {logging_mixin.py:188} INFO - [2024-08-31T17:34:00.864+0000] {dagbag.py:355} ERROR - Failed to import: /opt/airflow/dags/weather_etl_dag.py
Traceback (most recent call last):
  File "/home/airflow/.local/lib/python3.12/site-packages/airflow/models/dagbag.py", line 351, in parse
    loader.exec_module(new_module)
  File "<frozen importlib._bootstrap_external>", line 995, in exec_module
  File "<frozen importlib._bootstrap>", line 488, in _call_with_frames_removed
  File "/opt/airflow/dags/weather_etl_dag.py", line 5, in <module>
    from weather_etl import install_packages, get_municipios, fetch_weather_data, translate_and_clean_data
  File "/opt/airflow/dags/weather_etl.py", line 5, in <module>
    from translate import Translator
ModuleNotFoundError: No module named 'translate'
[2024-08-31T17:34:00.893+0000] {processor.py:842} WARNING - No viable dags retrieved from /opt/airflow/dags/weather_etl_dag.py
[2024-08-31T17:34:00.991+0000] {processor.py:183} INFO - Processing /opt/airflow/dags/weather_etl_dag.py took 19.052 seconds
[2024-08-31T17:44:01.268+0000] {processor.py:161} INFO - Started process (PID=192) to work on /opt/airflow/dags/weather_etl_dag.py
[2024-08-31T17:44:01.270+0000] {processor.py:830} INFO - Processing file /opt/airflow/dags/weather_etl_dag.py for tasks to queue
[2024-08-31T17:44:01.280+0000] {logging_mixin.py:188} INFO - [2024-08-31T17:44:01.280+0000] {dagbag.py:545} INFO - Filling up the DagBag from /opt/airflow/dags/weather_etl_dag.py
[2024-08-31T17:44:02.345+0000] {logging_mixin.py:188} INFO - [2024-08-31T17:44:02.340+0000] {dagbag.py:355} ERROR - Failed to import: /opt/airflow/dags/weather_etl_dag.py
Traceback (most recent call last):
  File "/home/airflow/.local/lib/python3.12/site-packages/airflow/models/dagbag.py", line 351, in parse
    loader.exec_module(new_module)
  File "<frozen importlib._bootstrap_external>", line 995, in exec_module
  File "<frozen importlib._bootstrap>", line 488, in _call_with_frames_removed
  File "/opt/airflow/dags/weather_etl_dag.py", line 5, in <module>
    from weather_etl import install_packages, get_municipios, fetch_weather_data, translate_and_clean_data
  File "/opt/airflow/dags/weather_etl.py", line 5, in <module>
    from translate import Translator
ModuleNotFoundError: No module named 'translate'
[2024-08-31T17:44:02.347+0000] {processor.py:842} WARNING - No viable dags retrieved from /opt/airflow/dags/weather_etl_dag.py
[2024-08-31T17:44:03.032+0000] {processor.py:183} INFO - Processing /opt/airflow/dags/weather_etl_dag.py took 1.781 seconds
[2024-08-31T17:54:03.441+0000] {processor.py:161} INFO - Started process (PID=314) to work on /opt/airflow/dags/weather_etl_dag.py
[2024-08-31T17:54:03.442+0000] {processor.py:830} INFO - Processing file /opt/airflow/dags/weather_etl_dag.py for tasks to queue
[2024-08-31T17:54:03.443+0000] {logging_mixin.py:188} INFO - [2024-08-31T17:54:03.443+0000] {dagbag.py:545} INFO - Filling up the DagBag from /opt/airflow/dags/weather_etl_dag.py
[2024-08-31T17:54:03.860+0000] {logging_mixin.py:188} INFO - [2024-08-31T17:54:03.856+0000] {dagbag.py:355} ERROR - Failed to import: /opt/airflow/dags/weather_etl_dag.py
Traceback (most recent call last):
  File "/home/airflow/.local/lib/python3.12/site-packages/airflow/models/dagbag.py", line 351, in parse
    loader.exec_module(new_module)
  File "<frozen importlib._bootstrap_external>", line 995, in exec_module
  File "<frozen importlib._bootstrap>", line 488, in _call_with_frames_removed
  File "/opt/airflow/dags/weather_etl_dag.py", line 5, in <module>
    from weather_etl import install_packages, get_municipios, fetch_weather_data, translate_and_clean_data
  File "/opt/airflow/dags/weather_etl.py", line 5, in <module>
    from translate import Translator
ModuleNotFoundError: No module named 'translate'
[2024-08-31T17:54:03.862+0000] {processor.py:842} WARNING - No viable dags retrieved from /opt/airflow/dags/weather_etl_dag.py
[2024-08-31T17:54:04.222+0000] {processor.py:183} INFO - Processing /opt/airflow/dags/weather_etl_dag.py took 0.787 seconds
[2024-08-31T17:56:47.078+0000] {processor.py:161} INFO - Started process (PID=347) to work on /opt/airflow/dags/weather_etl_dag.py
[2024-08-31T17:56:47.079+0000] {processor.py:830} INFO - Processing file /opt/airflow/dags/weather_etl_dag.py for tasks to queue
[2024-08-31T17:56:47.081+0000] {logging_mixin.py:188} INFO - [2024-08-31T17:56:47.081+0000] {dagbag.py:545} INFO - Filling up the DagBag from /opt/airflow/dags/weather_etl_dag.py
[2024-08-31T17:56:47.555+0000] {logging_mixin.py:188} INFO - [2024-08-31T17:56:47.550+0000] {dagbag.py:355} ERROR - Failed to import: /opt/airflow/dags/weather_etl_dag.py
Traceback (most recent call last):
  File "/home/airflow/.local/lib/python3.12/site-packages/airflow/models/dagbag.py", line 351, in parse
    loader.exec_module(new_module)
  File "<frozen importlib._bootstrap_external>", line 995, in exec_module
  File "<frozen importlib._bootstrap>", line 488, in _call_with_frames_removed
  File "/opt/airflow/dags/weather_etl_dag.py", line 5, in <module>
    from weather_etl import get_municipios, fetch_weather_data, translate_and_clean_data
  File "/opt/airflow/dags/weather_etl.py", line 5, in <module>
    from translate import Translator
ModuleNotFoundError: No module named 'translate'
[2024-08-31T17:56:47.556+0000] {processor.py:842} WARNING - No viable dags retrieved from /opt/airflow/dags/weather_etl_dag.py
[2024-08-31T17:56:47.625+0000] {processor.py:183} INFO - Processing /opt/airflow/dags/weather_etl_dag.py took 0.555 seconds
[2024-08-31T18:01:35.088+0000] {processor.py:161} INFO - Started process (PID=58) to work on /opt/airflow/dags/weather_etl_dag.py
[2024-08-31T18:01:35.101+0000] {processor.py:830} INFO - Processing file /opt/airflow/dags/weather_etl_dag.py for tasks to queue
[2024-08-31T18:01:35.114+0000] {logging_mixin.py:188} INFO - [2024-08-31T18:01:35.113+0000] {dagbag.py:545} INFO - Filling up the DagBag from /opt/airflow/dags/weather_etl_dag.py
[2024-08-31T18:01:40.149+0000] {logging_mixin.py:188} INFO - [2024-08-31T18:01:40.143+0000] {dagbag.py:355} ERROR - Failed to import: /opt/airflow/dags/weather_etl_dag.py
Traceback (most recent call last):
  File "/home/airflow/.local/lib/python3.12/site-packages/airflow/models/dagbag.py", line 351, in parse
    loader.exec_module(new_module)
  File "<frozen importlib._bootstrap_external>", line 995, in exec_module
  File "<frozen importlib._bootstrap>", line 488, in _call_with_frames_removed
  File "/opt/airflow/dags/weather_etl_dag.py", line 5, in <module>
    from weather_etl import get_municipios, fetch_weather_data, translate_and_clean_data
  File "/opt/airflow/dags/weather_etl.py", line 5, in <module>
    from translate import Translator
ModuleNotFoundError: No module named 'translate'
[2024-08-31T18:01:40.150+0000] {processor.py:842} WARNING - No viable dags retrieved from /opt/airflow/dags/weather_etl_dag.py
[2024-08-31T18:01:40.230+0000] {processor.py:183} INFO - Processing /opt/airflow/dags/weather_etl_dag.py took 5.182 seconds
[2024-08-31T18:11:48.201+0000] {processor.py:161} INFO - Started process (PID=63) to work on /opt/airflow/dags/weather_etl_dag.py
[2024-08-31T18:11:48.209+0000] {processor.py:830} INFO - Processing file /opt/airflow/dags/weather_etl_dag.py for tasks to queue
[2024-08-31T18:11:48.232+0000] {logging_mixin.py:188} INFO - [2024-08-31T18:11:48.227+0000] {dagbag.py:545} INFO - Filling up the DagBag from /opt/airflow/dags/weather_etl_dag.py
[2024-08-31T18:11:52.574+0000] {logging_mixin.py:188} INFO - [2024-08-31T18:11:52.566+0000] {dagbag.py:355} ERROR - Failed to import: /opt/airflow/dags/weather_etl_dag.py
Traceback (most recent call last):
  File "/home/airflow/.local/lib/python3.12/site-packages/airflow/models/dagbag.py", line 351, in parse
    loader.exec_module(new_module)
  File "<frozen importlib._bootstrap_external>", line 995, in exec_module
  File "<frozen importlib._bootstrap>", line 488, in _call_with_frames_removed
  File "/opt/airflow/dags/weather_etl_dag.py", line 5, in <module>
    from weather_etl import get_municipios, fetch_weather_data, translate_and_clean_data
  File "/opt/airflow/dags/weather_etl.py", line 5, in <module>
    from translate import Translator
ModuleNotFoundError: No module named 'translate'
[2024-08-31T18:11:52.576+0000] {processor.py:842} WARNING - No viable dags retrieved from /opt/airflow/dags/weather_etl_dag.py
[2024-08-31T18:11:52.656+0000] {processor.py:183} INFO - Processing /opt/airflow/dags/weather_etl_dag.py took 4.501 seconds
[2024-08-31T18:18:13.107+0000] {processor.py:161} INFO - Started process (PID=139) to work on /opt/airflow/dags/weather_etl_dag.py
[2024-08-31T18:18:13.108+0000] {processor.py:830} INFO - Processing file /opt/airflow/dags/weather_etl_dag.py for tasks to queue
[2024-08-31T18:18:13.110+0000] {logging_mixin.py:188} INFO - [2024-08-31T18:18:13.109+0000] {dagbag.py:545} INFO - Filling up the DagBag from /opt/airflow/dags/weather_etl_dag.py
[2024-08-31T18:18:13.734+0000] {logging_mixin.py:188} INFO - [2024-08-31T18:18:13.729+0000] {dagbag.py:355} ERROR - Failed to import: /opt/airflow/dags/weather_etl_dag.py
Traceback (most recent call last):
  File "/home/airflow/.local/lib/python3.12/site-packages/airflow/models/dagbag.py", line 351, in parse
    loader.exec_module(new_module)
  File "<frozen importlib._bootstrap_external>", line 995, in exec_module
  File "<frozen importlib._bootstrap>", line 488, in _call_with_frames_removed
  File "/opt/airflow/dags/weather_etl_dag.py", line 5, in <module>
    from weather_etl import get_municipios, fetch_weather_data, translate_and_clean_data
  File "/opt/airflow/dags/weather_etl.py", line 5, in <module>
    from translate import Translator
ModuleNotFoundError: No module named 'translate'
[2024-08-31T18:18:13.736+0000] {processor.py:842} WARNING - No viable dags retrieved from /opt/airflow/dags/weather_etl_dag.py
[2024-08-31T18:18:13.791+0000] {processor.py:183} INFO - Processing /opt/airflow/dags/weather_etl_dag.py took 0.689 seconds
[2024-08-31T18:21:33.509+0000] {processor.py:161} INFO - Started process (PID=66) to work on /opt/airflow/dags/weather_etl_dag.py
[2024-08-31T18:21:33.514+0000] {processor.py:830} INFO - Processing file /opt/airflow/dags/weather_etl_dag.py for tasks to queue
[2024-08-31T18:21:33.535+0000] {logging_mixin.py:188} INFO - [2024-08-31T18:21:33.535+0000] {dagbag.py:545} INFO - Filling up the DagBag from /opt/airflow/dags/weather_etl_dag.py
[2024-08-31T18:21:40.173+0000] {logging_mixin.py:188} INFO - [2024-08-31T18:21:40.167+0000] {dagbag.py:355} ERROR - Failed to import: /opt/airflow/dags/weather_etl_dag.py
Traceback (most recent call last):
  File "/home/airflow/.local/lib/python3.12/site-packages/airflow/models/dagbag.py", line 351, in parse
    loader.exec_module(new_module)
  File "<frozen importlib._bootstrap_external>", line 995, in exec_module
  File "<frozen importlib._bootstrap>", line 488, in _call_with_frames_removed
  File "/opt/airflow/dags/weather_etl_dag.py", line 5, in <module>
    from weather_etl import get_municipios, fetch_weather_data, translate_and_clean_data
  File "/opt/airflow/dags/weather_etl.py", line 5, in <module>
    from translate import Translator
ModuleNotFoundError: No module named 'translate'
[2024-08-31T18:21:40.175+0000] {processor.py:842} WARNING - No viable dags retrieved from /opt/airflow/dags/weather_etl_dag.py
[2024-08-31T18:21:40.246+0000] {processor.py:183} INFO - Processing /opt/airflow/dags/weather_etl_dag.py took 6.761 seconds
[2024-08-31T18:22:34.681+0000] {processor.py:161} INFO - Started process (PID=53) to work on /opt/airflow/dags/weather_etl_dag.py
[2024-08-31T18:22:34.682+0000] {processor.py:830} INFO - Processing file /opt/airflow/dags/weather_etl_dag.py for tasks to queue
[2024-08-31T18:22:34.684+0000] {logging_mixin.py:188} INFO - [2024-08-31T18:22:34.684+0000] {dagbag.py:545} INFO - Filling up the DagBag from /opt/airflow/dags/weather_etl_dag.py
[2024-08-31T18:22:35.235+0000] {logging_mixin.py:188} INFO - [2024-08-31T18:22:35.208+0000] {dagbag.py:355} ERROR - Failed to import: /opt/airflow/dags/weather_etl_dag.py
Traceback (most recent call last):
  File "/home/airflow/.local/lib/python3.12/site-packages/airflow/models/dagbag.py", line 351, in parse
    loader.exec_module(new_module)
  File "<frozen importlib._bootstrap_external>", line 995, in exec_module
  File "<frozen importlib._bootstrap>", line 488, in _call_with_frames_removed
  File "/opt/airflow/dags/weather_etl_dag.py", line 5, in <module>
    from weather_etl import get_municipios, fetch_weather_data, translate_and_clean_data
  File "/opt/airflow/dags/weather_etl.py", line 5, in <module>
    from translate import Translator
ModuleNotFoundError: No module named 'translate'
[2024-08-31T18:22:35.237+0000] {processor.py:842} WARNING - No viable dags retrieved from /opt/airflow/dags/weather_etl_dag.py
[2024-08-31T18:22:35.324+0000] {processor.py:183} INFO - Processing /opt/airflow/dags/weather_etl_dag.py took 0.650 seconds
[2024-08-31T18:30:50.750+0000] {processor.py:161} INFO - Started process (PID=69) to work on /opt/airflow/dags/weather_etl_dag.py
[2024-08-31T18:30:50.784+0000] {processor.py:830} INFO - Processing file /opt/airflow/dags/weather_etl_dag.py for tasks to queue
[2024-08-31T18:30:50.802+0000] {logging_mixin.py:188} INFO - [2024-08-31T18:30:50.802+0000] {dagbag.py:545} INFO - Filling up the DagBag from /opt/airflow/dags/weather_etl_dag.py
[2024-08-31T18:30:56.317+0000] {logging_mixin.py:188} INFO - [2024-08-31T18:30:56.310+0000] {dagbag.py:355} ERROR - Failed to import: /opt/airflow/dags/weather_etl_dag.py
Traceback (most recent call last):
  File "/home/airflow/.local/lib/python3.12/site-packages/airflow/models/dagbag.py", line 351, in parse
    loader.exec_module(new_module)
  File "<frozen importlib._bootstrap_external>", line 995, in exec_module
  File "<frozen importlib._bootstrap>", line 488, in _call_with_frames_removed
  File "/opt/airflow/dags/weather_etl_dag.py", line 5, in <module>
    from weather_etl import get_municipios, fetch_weather_data, translate_and_clean_data
  File "/opt/airflow/dags/weather_etl.py", line 5, in <module>
    from translate import Translator
ModuleNotFoundError: No module named 'translate'
[2024-08-31T18:30:56.319+0000] {processor.py:842} WARNING - No viable dags retrieved from /opt/airflow/dags/weather_etl_dag.py
[2024-08-31T18:30:56.402+0000] {processor.py:183} INFO - Processing /opt/airflow/dags/weather_etl_dag.py took 5.661 seconds
[2024-08-31T18:40:57.381+0000] {processor.py:161} INFO - Started process (PID=193) to work on /opt/airflow/dags/weather_etl_dag.py
[2024-08-31T18:40:57.382+0000] {processor.py:830} INFO - Processing file /opt/airflow/dags/weather_etl_dag.py for tasks to queue
[2024-08-31T18:40:57.389+0000] {logging_mixin.py:188} INFO - [2024-08-31T18:40:57.389+0000] {dagbag.py:545} INFO - Filling up the DagBag from /opt/airflow/dags/weather_etl_dag.py
[2024-08-31T18:40:58.055+0000] {logging_mixin.py:188} INFO - [2024-08-31T18:40:58.049+0000] {dagbag.py:355} ERROR - Failed to import: /opt/airflow/dags/weather_etl_dag.py
Traceback (most recent call last):
  File "/home/airflow/.local/lib/python3.12/site-packages/airflow/models/dagbag.py", line 351, in parse
    loader.exec_module(new_module)
  File "<frozen importlib._bootstrap_external>", line 995, in exec_module
  File "<frozen importlib._bootstrap>", line 488, in _call_with_frames_removed
  File "/opt/airflow/dags/weather_etl_dag.py", line 5, in <module>
    from weather_etl import get_municipios, fetch_weather_data, translate_and_clean_data
  File "/opt/airflow/dags/weather_etl.py", line 5, in <module>
    from translate import Translator
ModuleNotFoundError: No module named 'translate'
[2024-08-31T18:40:58.057+0000] {processor.py:842} WARNING - No viable dags retrieved from /opt/airflow/dags/weather_etl_dag.py
[2024-08-31T18:40:58.122+0000] {processor.py:183} INFO - Processing /opt/airflow/dags/weather_etl_dag.py took 0.759 seconds
[2024-08-31T18:50:59.127+0000] {processor.py:161} INFO - Started process (PID=324) to work on /opt/airflow/dags/weather_etl_dag.py
[2024-08-31T18:50:59.128+0000] {processor.py:830} INFO - Processing file /opt/airflow/dags/weather_etl_dag.py for tasks to queue
[2024-08-31T18:50:59.132+0000] {logging_mixin.py:188} INFO - [2024-08-31T18:50:59.131+0000] {dagbag.py:545} INFO - Filling up the DagBag from /opt/airflow/dags/weather_etl_dag.py
[2024-08-31T18:50:59.575+0000] {logging_mixin.py:188} INFO - [2024-08-31T18:50:59.571+0000] {dagbag.py:355} ERROR - Failed to import: /opt/airflow/dags/weather_etl_dag.py
Traceback (most recent call last):
  File "/home/airflow/.local/lib/python3.12/site-packages/airflow/models/dagbag.py", line 351, in parse
    loader.exec_module(new_module)
  File "<frozen importlib._bootstrap_external>", line 995, in exec_module
  File "<frozen importlib._bootstrap>", line 488, in _call_with_frames_removed
  File "/opt/airflow/dags/weather_etl_dag.py", line 5, in <module>
    from weather_etl import get_municipios, fetch_weather_data, translate_and_clean_data
  File "/opt/airflow/dags/weather_etl.py", line 5, in <module>
    from translate import Translator
ModuleNotFoundError: No module named 'translate'
[2024-08-31T18:50:59.576+0000] {processor.py:842} WARNING - No viable dags retrieved from /opt/airflow/dags/weather_etl_dag.py
[2024-08-31T18:50:59.630+0000] {processor.py:183} INFO - Processing /opt/airflow/dags/weather_etl_dag.py took 0.510 seconds
[2024-08-31T19:01:00.010+0000] {processor.py:161} INFO - Started process (PID=448) to work on /opt/airflow/dags/weather_etl_dag.py
[2024-08-31T19:01:00.016+0000] {processor.py:830} INFO - Processing file /opt/airflow/dags/weather_etl_dag.py for tasks to queue
[2024-08-31T19:01:00.026+0000] {logging_mixin.py:188} INFO - [2024-08-31T19:01:00.019+0000] {dagbag.py:545} INFO - Filling up the DagBag from /opt/airflow/dags/weather_etl_dag.py
[2024-08-31T19:01:00.504+0000] {logging_mixin.py:188} INFO - [2024-08-31T19:01:00.498+0000] {dagbag.py:355} ERROR - Failed to import: /opt/airflow/dags/weather_etl_dag.py
Traceback (most recent call last):
  File "/home/airflow/.local/lib/python3.12/site-packages/airflow/models/dagbag.py", line 351, in parse
    loader.exec_module(new_module)
  File "<frozen importlib._bootstrap_external>", line 995, in exec_module
  File "<frozen importlib._bootstrap>", line 488, in _call_with_frames_removed
  File "/opt/airflow/dags/weather_etl_dag.py", line 5, in <module>
    from weather_etl import get_municipios, fetch_weather_data, translate_and_clean_data
  File "/opt/airflow/dags/weather_etl.py", line 5, in <module>
    from translate import Translator
ModuleNotFoundError: No module named 'translate'
[2024-08-31T19:01:00.508+0000] {processor.py:842} WARNING - No viable dags retrieved from /opt/airflow/dags/weather_etl_dag.py
[2024-08-31T19:01:00.721+0000] {processor.py:183} INFO - Processing /opt/airflow/dags/weather_etl_dag.py took 0.719 seconds
[2024-08-31T19:11:01.017+0000] {processor.py:161} INFO - Started process (PID=573) to work on /opt/airflow/dags/weather_etl_dag.py
[2024-08-31T19:11:01.018+0000] {processor.py:830} INFO - Processing file /opt/airflow/dags/weather_etl_dag.py for tasks to queue
[2024-08-31T19:11:01.021+0000] {logging_mixin.py:188} INFO - [2024-08-31T19:11:01.021+0000] {dagbag.py:545} INFO - Filling up the DagBag from /opt/airflow/dags/weather_etl_dag.py
[2024-08-31T19:11:01.681+0000] {logging_mixin.py:188} INFO - [2024-08-31T19:11:01.678+0000] {dagbag.py:355} ERROR - Failed to import: /opt/airflow/dags/weather_etl_dag.py
Traceback (most recent call last):
  File "/home/airflow/.local/lib/python3.12/site-packages/airflow/models/dagbag.py", line 351, in parse
    loader.exec_module(new_module)
  File "<frozen importlib._bootstrap_external>", line 995, in exec_module
  File "<frozen importlib._bootstrap>", line 488, in _call_with_frames_removed
  File "/opt/airflow/dags/weather_etl_dag.py", line 11, in <module>
    from translate import Translator
ModuleNotFoundError: No module named 'translate'
[2024-08-31T19:11:01.700+0000] {processor.py:842} WARNING - No viable dags retrieved from /opt/airflow/dags/weather_etl_dag.py
[2024-08-31T19:11:01.805+0000] {processor.py:183} INFO - Processing /opt/airflow/dags/weather_etl_dag.py took 0.793 seconds
[2024-08-31T19:15:12.687+0000] {processor.py:161} INFO - Started process (PID=59) to work on /opt/airflow/dags/weather_etl_dag.py
[2024-08-31T19:15:12.693+0000] {processor.py:830} INFO - Processing file /opt/airflow/dags/weather_etl_dag.py for tasks to queue
[2024-08-31T19:15:12.714+0000] {logging_mixin.py:188} INFO - [2024-08-31T19:15:12.713+0000] {dagbag.py:545} INFO - Filling up the DagBag from /opt/airflow/dags/weather_etl_dag.py
[2024-08-31T19:15:18.221+0000] {logging_mixin.py:188} INFO - [2024-08-31T19:15:18.218+0000] {dagbag.py:355} ERROR - Failed to import: /opt/airflow/dags/weather_etl_dag.py
Traceback (most recent call last):
  File "/home/airflow/.local/lib/python3.12/site-packages/airflow/models/dagbag.py", line 351, in parse
    loader.exec_module(new_module)
  File "<frozen importlib._bootstrap_external>", line 995, in exec_module
  File "<frozen importlib._bootstrap>", line 488, in _call_with_frames_removed
  File "/opt/airflow/dags/weather_etl_dag.py", line 11, in <module>
    from translate import Translator
ModuleNotFoundError: No module named 'translate'
[2024-08-31T19:15:18.222+0000] {processor.py:842} WARNING - No viable dags retrieved from /opt/airflow/dags/weather_etl_dag.py
[2024-08-31T19:15:19.357+0000] {processor.py:183} INFO - Processing /opt/airflow/dags/weather_etl_dag.py took 6.679 seconds
[2024-08-31T19:25:20.296+0000] {processor.py:161} INFO - Started process (PID=189) to work on /opt/airflow/dags/weather_etl_dag.py
[2024-08-31T19:25:20.297+0000] {processor.py:830} INFO - Processing file /opt/airflow/dags/weather_etl_dag.py for tasks to queue
[2024-08-31T19:25:20.300+0000] {logging_mixin.py:188} INFO - [2024-08-31T19:25:20.299+0000] {dagbag.py:545} INFO - Filling up the DagBag from /opt/airflow/dags/weather_etl_dag.py
[2024-08-31T19:25:20.804+0000] {logging_mixin.py:188} INFO - [2024-08-31T19:25:20.787+0000] {dagbag.py:355} ERROR - Failed to import: /opt/airflow/dags/weather_etl_dag.py
Traceback (most recent call last):
  File "/home/airflow/.local/lib/python3.12/site-packages/airflow/models/dagbag.py", line 351, in parse
    loader.exec_module(new_module)
  File "<frozen importlib._bootstrap_external>", line 995, in exec_module
  File "<frozen importlib._bootstrap>", line 488, in _call_with_frames_removed
  File "/opt/airflow/dags/weather_etl_dag.py", line 11, in <module>
    from translate import Translator
ModuleNotFoundError: No module named 'translate'
[2024-08-31T19:25:20.805+0000] {processor.py:842} WARNING - No viable dags retrieved from /opt/airflow/dags/weather_etl_dag.py
[2024-08-31T19:25:20.859+0000] {processor.py:183} INFO - Processing /opt/airflow/dags/weather_etl_dag.py took 0.571 seconds
[2024-08-31T19:29:18.949+0000] {processor.py:161} INFO - Started process (PID=238) to work on /opt/airflow/dags/weather_etl_dag.py
[2024-08-31T19:29:18.950+0000] {processor.py:830} INFO - Processing file /opt/airflow/dags/weather_etl_dag.py for tasks to queue
[2024-08-31T19:29:18.952+0000] {logging_mixin.py:188} INFO - [2024-08-31T19:29:18.952+0000] {dagbag.py:545} INFO - Filling up the DagBag from /opt/airflow/dags/weather_etl_dag.py
[2024-08-31T19:29:19.754+0000] {logging_mixin.py:188} INFO - [2024-08-31T19:29:19.750+0000] {dagbag.py:355} ERROR - Failed to import: /opt/airflow/dags/weather_etl_dag.py
Traceback (most recent call last):
  File "/home/airflow/.local/lib/python3.12/site-packages/airflow/models/dagbag.py", line 351, in parse
    loader.exec_module(new_module)
  File "<frozen importlib._bootstrap_external>", line 995, in exec_module
  File "<frozen importlib._bootstrap>", line 488, in _call_with_frames_removed
  File "/opt/airflow/dags/weather_etl_dag.py", line 12, in <module>
    import unidecode
ModuleNotFoundError: No module named 'unidecode'
[2024-08-31T19:29:19.755+0000] {processor.py:842} WARNING - No viable dags retrieved from /opt/airflow/dags/weather_etl_dag.py
[2024-08-31T19:29:20.607+0000] {processor.py:183} INFO - Processing /opt/airflow/dags/weather_etl_dag.py took 1.668 seconds
[2024-08-31T19:32:38.303+0000] {processor.py:161} INFO - Started process (PID=66) to work on /opt/airflow/dags/weather_etl_dag.py
[2024-08-31T19:32:38.329+0000] {processor.py:830} INFO - Processing file /opt/airflow/dags/weather_etl_dag.py for tasks to queue
[2024-08-31T19:32:38.331+0000] {logging_mixin.py:188} INFO - [2024-08-31T19:32:38.331+0000] {dagbag.py:545} INFO - Filling up the DagBag from /opt/airflow/dags/weather_etl_dag.py
[2024-08-31T19:32:43.621+0000] {logging_mixin.py:188} INFO - [2024-08-31T19:32:43.617+0000] {dagbag.py:355} ERROR - Failed to import: /opt/airflow/dags/weather_etl_dag.py
Traceback (most recent call last):
  File "/home/airflow/.local/lib/python3.12/site-packages/airflow/models/dagbag.py", line 351, in parse
    loader.exec_module(new_module)
  File "<frozen importlib._bootstrap_external>", line 995, in exec_module
  File "<frozen importlib._bootstrap>", line 488, in _call_with_frames_removed
  File "/opt/airflow/dags/weather_etl_dag.py", line 12, in <module>
    import unidecode
ModuleNotFoundError: No module named 'unidecode'
[2024-08-31T19:32:43.623+0000] {processor.py:842} WARNING - No viable dags retrieved from /opt/airflow/dags/weather_etl_dag.py
[2024-08-31T19:32:43.697+0000] {processor.py:183} INFO - Processing /opt/airflow/dags/weather_etl_dag.py took 5.411 seconds
[2024-08-31T19:33:34.716+0000] {processor.py:161} INFO - Started process (PID=54) to work on /opt/airflow/dags/weather_etl_dag.py
[2024-08-31T19:33:34.717+0000] {processor.py:830} INFO - Processing file /opt/airflow/dags/weather_etl_dag.py for tasks to queue
[2024-08-31T19:33:34.720+0000] {logging_mixin.py:188} INFO - [2024-08-31T19:33:34.719+0000] {dagbag.py:545} INFO - Filling up the DagBag from /opt/airflow/dags/weather_etl_dag.py
[2024-08-31T19:33:35.396+0000] {logging_mixin.py:188} INFO - [2024-08-31T19:33:35.383+0000] {dagbag.py:355} ERROR - Failed to import: /opt/airflow/dags/weather_etl_dag.py
Traceback (most recent call last):
  File "/home/airflow/.local/lib/python3.12/site-packages/airflow/models/dagbag.py", line 351, in parse
    loader.exec_module(new_module)
  File "<frozen importlib._bootstrap_external>", line 995, in exec_module
  File "<frozen importlib._bootstrap>", line 488, in _call_with_frames_removed
  File "/opt/airflow/dags/weather_etl_dag.py", line 12, in <module>
    import unidecode
ModuleNotFoundError: No module named 'unidecode'
[2024-08-31T19:33:35.397+0000] {processor.py:842} WARNING - No viable dags retrieved from /opt/airflow/dags/weather_etl_dag.py
[2024-08-31T19:33:35.489+0000] {processor.py:183} INFO - Processing /opt/airflow/dags/weather_etl_dag.py took 0.779 seconds
[2024-08-31T19:34:07.340+0000] {processor.py:161} INFO - Started process (PID=47) to work on /opt/airflow/dags/weather_etl_dag.py
[2024-08-31T19:34:07.344+0000] {processor.py:830} INFO - Processing file /opt/airflow/dags/weather_etl_dag.py for tasks to queue
[2024-08-31T19:34:07.347+0000] {logging_mixin.py:188} INFO - [2024-08-31T19:34:07.347+0000] {dagbag.py:545} INFO - Filling up the DagBag from /opt/airflow/dags/weather_etl_dag.py
[2024-08-31T19:34:07.692+0000] {logging_mixin.py:188} INFO - [2024-08-31T19:34:07.688+0000] {dagbag.py:355} ERROR - Failed to import: /opt/airflow/dags/weather_etl_dag.py
Traceback (most recent call last):
  File "/home/airflow/.local/lib/python3.12/site-packages/airflow/models/dagbag.py", line 351, in parse
    loader.exec_module(new_module)
  File "<frozen importlib._bootstrap_external>", line 995, in exec_module
  File "<frozen importlib._bootstrap>", line 488, in _call_with_frames_removed
  File "/opt/airflow/dags/weather_etl_dag.py", line 12, in <module>
    import unidecode
ModuleNotFoundError: No module named 'unidecode'
[2024-08-31T19:34:07.693+0000] {processor.py:842} WARNING - No viable dags retrieved from /opt/airflow/dags/weather_etl_dag.py
[2024-08-31T19:34:07.792+0000] {processor.py:183} INFO - Processing /opt/airflow/dags/weather_etl_dag.py took 0.457 seconds
[2024-08-31T19:44:08.526+0000] {processor.py:161} INFO - Started process (PID=176) to work on /opt/airflow/dags/weather_etl_dag.py
[2024-08-31T19:44:08.527+0000] {processor.py:830} INFO - Processing file /opt/airflow/dags/weather_etl_dag.py for tasks to queue
[2024-08-31T19:44:08.529+0000] {logging_mixin.py:188} INFO - [2024-08-31T19:44:08.528+0000] {dagbag.py:545} INFO - Filling up the DagBag from /opt/airflow/dags/weather_etl_dag.py
[2024-08-31T19:44:08.915+0000] {logging_mixin.py:188} INFO - [2024-08-31T19:44:08.912+0000] {dagbag.py:355} ERROR - Failed to import: /opt/airflow/dags/weather_etl_dag.py
Traceback (most recent call last):
  File "/home/airflow/.local/lib/python3.12/site-packages/airflow/models/dagbag.py", line 351, in parse
    loader.exec_module(new_module)
  File "<frozen importlib._bootstrap_external>", line 995, in exec_module
  File "<frozen importlib._bootstrap>", line 488, in _call_with_frames_removed
  File "/opt/airflow/dags/weather_etl_dag.py", line 12, in <module>
    import unidecode
ModuleNotFoundError: No module named 'unidecode'
[2024-08-31T19:44:08.916+0000] {processor.py:842} WARNING - No viable dags retrieved from /opt/airflow/dags/weather_etl_dag.py
[2024-08-31T19:44:09.226+0000] {processor.py:183} INFO - Processing /opt/airflow/dags/weather_etl_dag.py took 0.705 seconds
[2024-08-31T19:54:09.569+0000] {processor.py:161} INFO - Started process (PID=300) to work on /opt/airflow/dags/weather_etl_dag.py
[2024-08-31T19:54:09.570+0000] {processor.py:830} INFO - Processing file /opt/airflow/dags/weather_etl_dag.py for tasks to queue
[2024-08-31T19:54:09.572+0000] {logging_mixin.py:188} INFO - [2024-08-31T19:54:09.571+0000] {dagbag.py:545} INFO - Filling up the DagBag from /opt/airflow/dags/weather_etl_dag.py
[2024-08-31T19:54:10.104+0000] {logging_mixin.py:188} INFO - [2024-08-31T19:54:10.085+0000] {dagbag.py:355} ERROR - Failed to import: /opt/airflow/dags/weather_etl_dag.py
Traceback (most recent call last):
  File "/home/airflow/.local/lib/python3.12/site-packages/airflow/models/dagbag.py", line 351, in parse
    loader.exec_module(new_module)
  File "<frozen importlib._bootstrap_external>", line 995, in exec_module
  File "<frozen importlib._bootstrap>", line 488, in _call_with_frames_removed
  File "/opt/airflow/dags/weather_etl_dag.py", line 12, in <module>
    import unidecode
ModuleNotFoundError: No module named 'unidecode'
[2024-08-31T19:54:10.105+0000] {processor.py:842} WARNING - No viable dags retrieved from /opt/airflow/dags/weather_etl_dag.py
[2024-08-31T19:54:10.178+0000] {processor.py:183} INFO - Processing /opt/airflow/dags/weather_etl_dag.py took 0.614 seconds
[2024-08-31T20:04:10.512+0000] {processor.py:161} INFO - Started process (PID=421) to work on /opt/airflow/dags/weather_etl_dag.py
[2024-08-31T20:04:10.513+0000] {processor.py:830} INFO - Processing file /opt/airflow/dags/weather_etl_dag.py for tasks to queue
[2024-08-31T20:04:10.514+0000] {logging_mixin.py:188} INFO - [2024-08-31T20:04:10.514+0000] {dagbag.py:545} INFO - Filling up the DagBag from /opt/airflow/dags/weather_etl_dag.py
[2024-08-31T20:04:11.136+0000] {logging_mixin.py:188} INFO - [2024-08-31T20:04:11.133+0000] {dagbag.py:355} ERROR - Failed to import: /opt/airflow/dags/weather_etl_dag.py
Traceback (most recent call last):
  File "/home/airflow/.local/lib/python3.12/site-packages/airflow/models/dagbag.py", line 351, in parse
    loader.exec_module(new_module)
  File "<frozen importlib._bootstrap_external>", line 995, in exec_module
  File "<frozen importlib._bootstrap>", line 488, in _call_with_frames_removed
  File "/opt/airflow/dags/weather_etl_dag.py", line 12, in <module>
    import unidecode
ModuleNotFoundError: No module named 'unidecode'
[2024-08-31T20:04:11.137+0000] {processor.py:842} WARNING - No viable dags retrieved from /opt/airflow/dags/weather_etl_dag.py
[2024-08-31T20:04:11.194+0000] {processor.py:183} INFO - Processing /opt/airflow/dags/weather_etl_dag.py took 0.688 seconds
[2024-08-31T20:25:42.799+0000] {processor.py:161} INFO - Started process (PID=62) to work on /opt/airflow/dags/weather_etl_dag.py
[2024-08-31T20:25:42.800+0000] {processor.py:830} INFO - Processing file /opt/airflow/dags/weather_etl_dag.py for tasks to queue
[2024-08-31T20:25:42.810+0000] {logging_mixin.py:188} INFO - [2024-08-31T20:25:42.808+0000] {dagbag.py:545} INFO - Filling up the DagBag from /opt/airflow/dags/weather_etl_dag.py
[2024-08-31T20:25:48.669+0000] {logging_mixin.py:188} INFO - [2024-08-31T20:25:48.659+0000] {dagbag.py:355} ERROR - Failed to import: /opt/airflow/dags/weather_etl_dag.py
Traceback (most recent call last):
  File "/home/airflow/.local/lib/python3.12/site-packages/airflow/models/dagbag.py", line 351, in parse
    loader.exec_module(new_module)
  File "<frozen importlib._bootstrap_external>", line 995, in exec_module
  File "<frozen importlib._bootstrap>", line 488, in _call_with_frames_removed
  File "/opt/airflow/dags/weather_etl_dag.py", line 11, in <module>
    from translate import Translator
ModuleNotFoundError: No module named 'translate'
[2024-08-31T20:25:48.671+0000] {processor.py:842} WARNING - No viable dags retrieved from /opt/airflow/dags/weather_etl_dag.py
[2024-08-31T20:25:48.741+0000] {processor.py:183} INFO - Processing /opt/airflow/dags/weather_etl_dag.py took 5.960 seconds
[2024-08-31T20:35:49.481+0000] {processor.py:161} INFO - Started process (PID=186) to work on /opt/airflow/dags/weather_etl_dag.py
[2024-08-31T20:35:49.483+0000] {processor.py:830} INFO - Processing file /opt/airflow/dags/weather_etl_dag.py for tasks to queue
[2024-08-31T20:35:49.486+0000] {logging_mixin.py:188} INFO - [2024-08-31T20:35:49.485+0000] {dagbag.py:545} INFO - Filling up the DagBag from /opt/airflow/dags/weather_etl_dag.py
[2024-08-31T20:35:51.587+0000] {logging_mixin.py:188} INFO - [2024-08-31T20:35:51.583+0000] {dagbag.py:355} ERROR - Failed to import: /opt/airflow/dags/weather_etl_dag.py
Traceback (most recent call last):
  File "/home/airflow/.local/lib/python3.12/site-packages/airflow/models/dagbag.py", line 351, in parse
    loader.exec_module(new_module)
  File "<frozen importlib._bootstrap_external>", line 995, in exec_module
  File "<frozen importlib._bootstrap>", line 488, in _call_with_frames_removed
  File "/opt/airflow/dags/weather_etl_dag.py", line 11, in <module>
    from translate import Translator
ModuleNotFoundError: No module named 'translate'
[2024-08-31T20:35:51.589+0000] {processor.py:842} WARNING - No viable dags retrieved from /opt/airflow/dags/weather_etl_dag.py
[2024-08-31T20:35:51.635+0000] {processor.py:183} INFO - Processing /opt/airflow/dags/weather_etl_dag.py took 2.162 seconds
[2024-08-31T20:45:51.713+0000] {processor.py:161} INFO - Started process (PID=313) to work on /opt/airflow/dags/weather_etl_dag.py
[2024-08-31T20:45:51.714+0000] {processor.py:830} INFO - Processing file /opt/airflow/dags/weather_etl_dag.py for tasks to queue
[2024-08-31T20:45:51.717+0000] {logging_mixin.py:188} INFO - [2024-08-31T20:45:51.716+0000] {dagbag.py:545} INFO - Filling up the DagBag from /opt/airflow/dags/weather_etl_dag.py
[2024-08-31T20:45:52.475+0000] {logging_mixin.py:188} INFO - [2024-08-31T20:45:52.472+0000] {dagbag.py:355} ERROR - Failed to import: /opt/airflow/dags/weather_etl_dag.py
Traceback (most recent call last):
  File "/home/airflow/.local/lib/python3.12/site-packages/airflow/models/dagbag.py", line 351, in parse
    loader.exec_module(new_module)
  File "<frozen importlib._bootstrap_external>", line 995, in exec_module
  File "<frozen importlib._bootstrap>", line 488, in _call_with_frames_removed
  File "/opt/airflow/dags/weather_etl_dag.py", line 11, in <module>
    from translate import Translator
ModuleNotFoundError: No module named 'translate'
[2024-08-31T20:45:52.477+0000] {processor.py:842} WARNING - No viable dags retrieved from /opt/airflow/dags/weather_etl_dag.py
[2024-08-31T20:45:52.547+0000] {processor.py:183} INFO - Processing /opt/airflow/dags/weather_etl_dag.py took 0.845 seconds
[2024-08-31T20:53:43.091+0000] {processor.py:161} INFO - Started process (PID=67) to work on /opt/airflow/dags/weather_etl_dag.py
[2024-08-31T20:53:43.098+0000] {processor.py:830} INFO - Processing file /opt/airflow/dags/weather_etl_dag.py for tasks to queue
[2024-08-31T20:53:43.113+0000] {logging_mixin.py:188} INFO - [2024-08-31T20:53:43.113+0000] {dagbag.py:545} INFO - Filling up the DagBag from /opt/airflow/dags/weather_etl_dag.py
[2024-08-31T20:53:47.805+0000] {logging_mixin.py:188} INFO - [2024-08-31T20:53:47.802+0000] {dagbag.py:355} ERROR - Failed to import: /opt/airflow/dags/weather_etl_dag.py
Traceback (most recent call last):
  File "/home/airflow/.local/lib/python3.12/site-packages/airflow/models/dagbag.py", line 351, in parse
    loader.exec_module(new_module)
  File "<frozen importlib._bootstrap_external>", line 995, in exec_module
  File "<frozen importlib._bootstrap>", line 488, in _call_with_frames_removed
  File "/opt/airflow/dags/weather_etl_dag.py", line 11, in <module>
    from translate import Translator
ModuleNotFoundError: No module named 'translate'
[2024-08-31T20:53:47.806+0000] {processor.py:842} WARNING - No viable dags retrieved from /opt/airflow/dags/weather_etl_dag.py
[2024-08-31T20:53:47.972+0000] {processor.py:183} INFO - Processing /opt/airflow/dags/weather_etl_dag.py took 4.898 seconds
[2024-08-31T21:03:48.500+0000] {processor.py:161} INFO - Started process (PID=191) to work on /opt/airflow/dags/weather_etl_dag.py
[2024-08-31T21:03:48.500+0000] {processor.py:830} INFO - Processing file /opt/airflow/dags/weather_etl_dag.py for tasks to queue
[2024-08-31T21:03:48.502+0000] {logging_mixin.py:188} INFO - [2024-08-31T21:03:48.502+0000] {dagbag.py:545} INFO - Filling up the DagBag from /opt/airflow/dags/weather_etl_dag.py
[2024-08-31T21:03:48.972+0000] {logging_mixin.py:188} INFO - [2024-08-31T21:03:48.966+0000] {dagbag.py:355} ERROR - Failed to import: /opt/airflow/dags/weather_etl_dag.py
Traceback (most recent call last):
  File "/home/airflow/.local/lib/python3.12/site-packages/airflow/models/dagbag.py", line 351, in parse
    loader.exec_module(new_module)
  File "<frozen importlib._bootstrap_external>", line 995, in exec_module
  File "<frozen importlib._bootstrap>", line 488, in _call_with_frames_removed
  File "/opt/airflow/dags/weather_etl_dag.py", line 11, in <module>
    from translate import Translator
ModuleNotFoundError: No module named 'translate'
[2024-08-31T21:03:48.973+0000] {processor.py:842} WARNING - No viable dags retrieved from /opt/airflow/dags/weather_etl_dag.py
[2024-08-31T21:03:49.036+0000] {processor.py:183} INFO - Processing /opt/airflow/dags/weather_etl_dag.py took 0.541 seconds
[2024-08-31T21:09:44.998+0000] {processor.py:161} INFO - Started process (PID=64) to work on /opt/airflow/dags/weather_etl_dag.py
[2024-08-31T21:09:45.014+0000] {processor.py:830} INFO - Processing file /opt/airflow/dags/weather_etl_dag.py for tasks to queue
[2024-08-31T21:09:45.027+0000] {logging_mixin.py:188} INFO - [2024-08-31T21:09:45.026+0000] {dagbag.py:545} INFO - Filling up the DagBag from /opt/airflow/dags/weather_etl_dag.py
[2024-08-31T21:09:50.559+0000] {logging_mixin.py:188} INFO - [2024-08-31T21:09:50.316+0000] {dagbag.py:355} ERROR - Failed to import: /opt/airflow/dags/weather_etl_dag.py
Traceback (most recent call last):
  File "/home/airflow/.local/lib/python3.12/site-packages/airflow/models/dagbag.py", line 351, in parse
    loader.exec_module(new_module)
  File "<frozen importlib._bootstrap_external>", line 995, in exec_module
  File "<frozen importlib._bootstrap>", line 488, in _call_with_frames_removed
  File "/opt/airflow/dags/weather_etl_dag.py", line 11, in <module>
    from translate import Translator
ModuleNotFoundError: No module named 'translate'
[2024-08-31T21:09:50.660+0000] {processor.py:842} WARNING - No viable dags retrieved from /opt/airflow/dags/weather_etl_dag.py
[2024-08-31T21:09:50.829+0000] {processor.py:183} INFO - Processing /opt/airflow/dags/weather_etl_dag.py took 5.838 seconds
[2024-08-31T21:19:51.742+0000] {processor.py:161} INFO - Started process (PID=188) to work on /opt/airflow/dags/weather_etl_dag.py
[2024-08-31T21:19:51.743+0000] {processor.py:830} INFO - Processing file /opt/airflow/dags/weather_etl_dag.py for tasks to queue
[2024-08-31T21:19:51.746+0000] {logging_mixin.py:188} INFO - [2024-08-31T21:19:51.745+0000] {dagbag.py:545} INFO - Filling up the DagBag from /opt/airflow/dags/weather_etl_dag.py
[2024-08-31T21:19:52.035+0000] {logging_mixin.py:188} INFO - [2024-08-31T21:19:52.032+0000] {dagbag.py:355} ERROR - Failed to import: /opt/airflow/dags/weather_etl_dag.py
Traceback (most recent call last):
  File "/home/airflow/.local/lib/python3.12/site-packages/airflow/models/dagbag.py", line 351, in parse
    loader.exec_module(new_module)
  File "<frozen importlib._bootstrap_external>", line 995, in exec_module
  File "<frozen importlib._bootstrap>", line 488, in _call_with_frames_removed
  File "/opt/airflow/dags/weather_etl_dag.py", line 11, in <module>
    from translate import Translator
ModuleNotFoundError: No module named 'translate'
[2024-08-31T21:19:52.036+0000] {processor.py:842} WARNING - No viable dags retrieved from /opt/airflow/dags/weather_etl_dag.py
[2024-08-31T21:19:52.087+0000] {processor.py:183} INFO - Processing /opt/airflow/dags/weather_etl_dag.py took 0.350 seconds
[2024-08-31T21:29:52.660+0000] {processor.py:161} INFO - Started process (PID=311) to work on /opt/airflow/dags/weather_etl_dag.py
[2024-08-31T21:29:52.661+0000] {processor.py:830} INFO - Processing file /opt/airflow/dags/weather_etl_dag.py for tasks to queue
[2024-08-31T21:29:52.663+0000] {logging_mixin.py:188} INFO - [2024-08-31T21:29:52.662+0000] {dagbag.py:545} INFO - Filling up the DagBag from /opt/airflow/dags/weather_etl_dag.py
[2024-08-31T21:29:53.066+0000] {logging_mixin.py:188} INFO - [2024-08-31T21:29:53.063+0000] {dagbag.py:355} ERROR - Failed to import: /opt/airflow/dags/weather_etl_dag.py
Traceback (most recent call last):
  File "/home/airflow/.local/lib/python3.12/site-packages/airflow/models/dagbag.py", line 351, in parse
    loader.exec_module(new_module)
  File "<frozen importlib._bootstrap_external>", line 995, in exec_module
  File "<frozen importlib._bootstrap>", line 488, in _call_with_frames_removed
  File "/opt/airflow/dags/weather_etl_dag.py", line 11, in <module>
    from translate import Translator
ModuleNotFoundError: No module named 'translate'
[2024-08-31T21:29:53.067+0000] {processor.py:842} WARNING - No viable dags retrieved from /opt/airflow/dags/weather_etl_dag.py
[2024-08-31T21:29:53.140+0000] {processor.py:183} INFO - Processing /opt/airflow/dags/weather_etl_dag.py took 0.484 seconds
[2024-08-31T21:43:08.158+0000] {processor.py:161} INFO - Started process (PID=56) to work on /opt/airflow/dags/weather_etl_dag.py
[2024-08-31T21:43:08.164+0000] {processor.py:830} INFO - Processing file /opt/airflow/dags/weather_etl_dag.py for tasks to queue
[2024-08-31T21:43:08.168+0000] {logging_mixin.py:188} INFO - [2024-08-31T21:43:08.168+0000] {dagbag.py:545} INFO - Filling up the DagBag from /opt/airflow/dags/weather_etl_dag.py
[2024-08-31T21:43:13.902+0000] {logging_mixin.py:188} INFO - [2024-08-31T21:43:13.898+0000] {dagbag.py:355} ERROR - Failed to import: /opt/airflow/dags/weather_etl_dag.py
Traceback (most recent call last):
  File "/home/airflow/.local/lib/python3.12/site-packages/airflow/models/dagbag.py", line 351, in parse
    loader.exec_module(new_module)
  File "<frozen importlib._bootstrap_external>", line 995, in exec_module
  File "<frozen importlib._bootstrap>", line 488, in _call_with_frames_removed
  File "/opt/airflow/dags/weather_etl_dag.py", line 11, in <module>
    from translate import Translator
ModuleNotFoundError: No module named 'translate'
[2024-08-31T21:43:13.903+0000] {processor.py:842} WARNING - No viable dags retrieved from /opt/airflow/dags/weather_etl_dag.py
[2024-08-31T21:43:14.001+0000] {processor.py:183} INFO - Processing /opt/airflow/dags/weather_etl_dag.py took 5.868 seconds
[2024-08-31T21:52:45.297+0000] {processor.py:161} INFO - Started process (PID=66) to work on /opt/airflow/dags/weather_etl_dag.py
[2024-08-31T21:52:45.344+0000] {processor.py:830} INFO - Processing file /opt/airflow/dags/weather_etl_dag.py for tasks to queue
[2024-08-31T21:52:45.350+0000] {logging_mixin.py:188} INFO - [2024-08-31T21:52:45.349+0000] {dagbag.py:545} INFO - Filling up the DagBag from /opt/airflow/dags/weather_etl_dag.py
[2024-08-31T21:52:54.926+0000] {logging_mixin.py:188} INFO - [2024-08-31T21:52:54.895+0000] {dagbag.py:355} ERROR - Failed to import: /opt/airflow/dags/weather_etl_dag.py
Traceback (most recent call last):
  File "/home/airflow/.local/lib/python3.12/site-packages/airflow/models/dagbag.py", line 351, in parse
    loader.exec_module(new_module)
  File "<frozen importlib._bootstrap_external>", line 995, in exec_module
  File "<frozen importlib._bootstrap>", line 488, in _call_with_frames_removed
  File "/opt/airflow/dags/weather_etl_dag.py", line 11, in <module>
    from translate import Translator
ModuleNotFoundError: No module named 'translate'
[2024-08-31T21:52:54.927+0000] {processor.py:842} WARNING - No viable dags retrieved from /opt/airflow/dags/weather_etl_dag.py
[2024-08-31T21:52:55.592+0000] {processor.py:183} INFO - Processing /opt/airflow/dags/weather_etl_dag.py took 10.302 seconds
[2024-08-31T22:06:00.063+0000] {processor.py:161} INFO - Started process (PID=81) to work on /opt/airflow/dags/weather_etl_dag.py
[2024-08-31T22:06:00.092+0000] {processor.py:830} INFO - Processing file /opt/airflow/dags/weather_etl_dag.py for tasks to queue
[2024-08-31T22:06:00.121+0000] {logging_mixin.py:188} INFO - [2024-08-31T22:06:00.121+0000] {dagbag.py:545} INFO - Filling up the DagBag from /opt/airflow/dags/weather_etl_dag.py
[2024-08-31T22:06:04.057+0000] {logging_mixin.py:188} INFO - [2024-08-31T22:06:04.039+0000] {dagbag.py:355} ERROR - Failed to import: /opt/airflow/dags/weather_etl_dag.py
Traceback (most recent call last):
  File "/home/airflow/.local/lib/python3.12/site-packages/airflow/models/dagbag.py", line 351, in parse
    loader.exec_module(new_module)
  File "<frozen importlib._bootstrap_external>", line 995, in exec_module
  File "<frozen importlib._bootstrap>", line 488, in _call_with_frames_removed
  File "/opt/airflow/dags/weather_etl_dag.py", line 11, in <module>
    from translate import Translator
ModuleNotFoundError: No module named 'translate'
[2024-08-31T22:06:04.058+0000] {processor.py:842} WARNING - No viable dags retrieved from /opt/airflow/dags/weather_etl_dag.py
[2024-08-31T22:06:04.153+0000] {processor.py:183} INFO - Processing /opt/airflow/dags/weather_etl_dag.py took 4.100 seconds
[2024-08-31T22:07:15.329+0000] {processor.py:161} INFO - Started process (PID=58) to work on /opt/airflow/dags/weather_etl_dag.py
[2024-08-31T22:07:15.330+0000] {processor.py:830} INFO - Processing file /opt/airflow/dags/weather_etl_dag.py for tasks to queue
[2024-08-31T22:07:15.332+0000] {logging_mixin.py:188} INFO - [2024-08-31T22:07:15.332+0000] {dagbag.py:545} INFO - Filling up the DagBag from /opt/airflow/dags/weather_etl_dag.py
[2024-08-31T22:07:15.628+0000] {logging_mixin.py:188} INFO - [2024-08-31T22:07:15.625+0000] {dagbag.py:355} ERROR - Failed to import: /opt/airflow/dags/weather_etl_dag.py
Traceback (most recent call last):
  File "/home/airflow/.local/lib/python3.12/site-packages/airflow/models/dagbag.py", line 351, in parse
    loader.exec_module(new_module)
  File "<frozen importlib._bootstrap_external>", line 995, in exec_module
  File "<frozen importlib._bootstrap>", line 488, in _call_with_frames_removed
  File "/opt/airflow/dags/weather_etl_dag.py", line 11, in <module>
    from translate import Translator
ModuleNotFoundError: No module named 'translate'
[2024-08-31T22:07:15.712+0000] {processor.py:842} WARNING - No viable dags retrieved from /opt/airflow/dags/weather_etl_dag.py
[2024-08-31T22:07:16.001+0000] {processor.py:183} INFO - Processing /opt/airflow/dags/weather_etl_dag.py took 0.679 seconds
[2024-08-31T22:17:16.922+0000] {processor.py:161} INFO - Started process (PID=181) to work on /opt/airflow/dags/weather_etl_dag.py
[2024-08-31T22:17:16.923+0000] {processor.py:830} INFO - Processing file /opt/airflow/dags/weather_etl_dag.py for tasks to queue
[2024-08-31T22:17:16.924+0000] {logging_mixin.py:188} INFO - [2024-08-31T22:17:16.924+0000] {dagbag.py:545} INFO - Filling up the DagBag from /opt/airflow/dags/weather_etl_dag.py
[2024-08-31T22:17:17.345+0000] {logging_mixin.py:188} INFO - [2024-08-31T22:17:17.341+0000] {dagbag.py:355} ERROR - Failed to import: /opt/airflow/dags/weather_etl_dag.py
Traceback (most recent call last):
  File "/home/airflow/.local/lib/python3.12/site-packages/airflow/models/dagbag.py", line 351, in parse
    loader.exec_module(new_module)
  File "<frozen importlib._bootstrap_external>", line 995, in exec_module
  File "<frozen importlib._bootstrap>", line 488, in _call_with_frames_removed
  File "/opt/airflow/dags/weather_etl_dag.py", line 11, in <module>
    from translate import Translator
ModuleNotFoundError: No module named 'translate'
[2024-08-31T22:17:17.346+0000] {processor.py:842} WARNING - No viable dags retrieved from /opt/airflow/dags/weather_etl_dag.py
[2024-08-31T22:17:17.441+0000] {processor.py:183} INFO - Processing /opt/airflow/dags/weather_etl_dag.py took 0.524 seconds
[2024-08-31T22:18:07.301+0000] {processor.py:161} INFO - Started process (PID=195) to work on /opt/airflow/dags/weather_etl_dag.py
[2024-08-31T22:18:07.304+0000] {processor.py:830} INFO - Processing file /opt/airflow/dags/weather_etl_dag.py for tasks to queue
[2024-08-31T22:18:07.306+0000] {logging_mixin.py:188} INFO - [2024-08-31T22:18:07.305+0000] {dagbag.py:545} INFO - Filling up the DagBag from /opt/airflow/dags/weather_etl_dag.py
[2024-08-31T22:18:08.407+0000] {logging_mixin.py:188} INFO - [2024-08-31T22:18:08.372+0000] {dagbag.py:355} ERROR - Failed to import: /opt/airflow/dags/weather_etl_dag.py
Traceback (most recent call last):
  File "/home/airflow/.local/lib/python3.12/site-packages/airflow/models/dagbag.py", line 351, in parse
    loader.exec_module(new_module)
  File "<frozen importlib._bootstrap_external>", line 995, in exec_module
  File "<frozen importlib._bootstrap>", line 488, in _call_with_frames_removed
  File "/opt/airflow/dags/weather_etl_dag.py", line 5, in <module>
    from weather_etl import get_municipios, fetch_weather_data, translate_and_clean_data
  File "/opt/airflow/dags/weather_etl.py", line 5, in <module>
    from translate import Translator
ModuleNotFoundError: No module named 'translate'
[2024-08-31T22:18:08.409+0000] {processor.py:842} WARNING - No viable dags retrieved from /opt/airflow/dags/weather_etl_dag.py
[2024-08-31T22:18:08.520+0000] {processor.py:183} INFO - Processing /opt/airflow/dags/weather_etl_dag.py took 1.223 seconds
[2024-08-31T22:21:05.450+0000] {processor.py:161} INFO - Started process (PID=234) to work on /opt/airflow/dags/weather_etl_dag.py
[2024-08-31T22:21:05.451+0000] {processor.py:830} INFO - Processing file /opt/airflow/dags/weather_etl_dag.py for tasks to queue
[2024-08-31T22:21:05.456+0000] {logging_mixin.py:188} INFO - [2024-08-31T22:21:05.455+0000] {dagbag.py:545} INFO - Filling up the DagBag from /opt/airflow/dags/weather_etl_dag.py
[2024-08-31T22:21:06.371+0000] {logging_mixin.py:188} INFO - [2024-08-31T22:21:06.366+0000] {dagbag.py:355} ERROR - Failed to import: /opt/airflow/dags/weather_etl_dag.py
Traceback (most recent call last):
  File "/home/airflow/.local/lib/python3.12/site-packages/airflow/models/dagbag.py", line 351, in parse
    loader.exec_module(new_module)
  File "<frozen importlib._bootstrap_external>", line 995, in exec_module
  File "<frozen importlib._bootstrap>", line 488, in _call_with_frames_removed
  File "/opt/airflow/dags/weather_etl_dag.py", line 5, in <module>
    from weather_etl import get_municipios, fetch_weather_data, translate_and_clean_data
  File "/opt/airflow/dags/weather_etl.py", line 5, in <module>
    from translate import Translator
ModuleNotFoundError: No module named 'translate'
[2024-08-31T22:21:06.373+0000] {processor.py:842} WARNING - No viable dags retrieved from /opt/airflow/dags/weather_etl_dag.py
[2024-08-31T22:21:06.432+0000] {processor.py:183} INFO - Processing /opt/airflow/dags/weather_etl_dag.py took 0.990 seconds
[2024-08-31T22:24:47.142+0000] {processor.py:161} INFO - Started process (PID=63) to work on /opt/airflow/dags/weather_etl_dag.py
[2024-08-31T22:24:47.143+0000] {processor.py:830} INFO - Processing file /opt/airflow/dags/weather_etl_dag.py for tasks to queue
[2024-08-31T22:24:47.154+0000] {logging_mixin.py:188} INFO - [2024-08-31T22:24:47.154+0000] {dagbag.py:545} INFO - Filling up the DagBag from /opt/airflow/dags/weather_etl_dag.py
[2024-08-31T22:24:52.268+0000] {logging_mixin.py:188} INFO - [2024-08-31T22:24:52.259+0000] {dagbag.py:355} ERROR - Failed to import: /opt/airflow/dags/weather_etl_dag.py
Traceback (most recent call last):
  File "/home/airflow/.local/lib/python3.12/site-packages/airflow/models/dagbag.py", line 351, in parse
    loader.exec_module(new_module)
  File "<frozen importlib._bootstrap_external>", line 995, in exec_module
  File "<frozen importlib._bootstrap>", line 488, in _call_with_frames_removed
  File "/opt/airflow/dags/weather_etl_dag.py", line 5, in <module>
    from weather_etl import get_municipios, fetch_weather_data, translate_and_clean_data
  File "/opt/airflow/dags/weather_etl.py", line 5, in <module>
    from translate import Translator
ModuleNotFoundError: No module named 'translate'
[2024-08-31T22:24:52.269+0000] {processor.py:842} WARNING - No viable dags retrieved from /opt/airflow/dags/weather_etl_dag.py
[2024-08-31T22:24:52.404+0000] {processor.py:183} INFO - Processing /opt/airflow/dags/weather_etl_dag.py took 5.290 seconds
[2024-08-31T22:25:45.894+0000] {processor.py:161} INFO - Started process (PID=53) to work on /opt/airflow/dags/weather_etl_dag.py
[2024-08-31T22:25:45.895+0000] {processor.py:830} INFO - Processing file /opt/airflow/dags/weather_etl_dag.py for tasks to queue
[2024-08-31T22:25:45.898+0000] {logging_mixin.py:188} INFO - [2024-08-31T22:25:45.898+0000] {dagbag.py:545} INFO - Filling up the DagBag from /opt/airflow/dags/weather_etl_dag.py
[2024-08-31T22:25:46.284+0000] {logging_mixin.py:188} INFO - [2024-08-31T22:25:46.277+0000] {dagbag.py:355} ERROR - Failed to import: /opt/airflow/dags/weather_etl_dag.py
Traceback (most recent call last):
  File "/home/airflow/.local/lib/python3.12/site-packages/airflow/models/dagbag.py", line 351, in parse
    loader.exec_module(new_module)
  File "<frozen importlib._bootstrap_external>", line 995, in exec_module
  File "<frozen importlib._bootstrap>", line 488, in _call_with_frames_removed
  File "/opt/airflow/dags/weather_etl_dag.py", line 5, in <module>
    from weather_etl import get_municipios, fetch_weather_data, translate_and_clean_data
  File "/opt/airflow/dags/weather_etl.py", line 5, in <module>
    from translate import Translator
ModuleNotFoundError: No module named 'translate'
[2024-08-31T22:25:46.285+0000] {processor.py:842} WARNING - No viable dags retrieved from /opt/airflow/dags/weather_etl_dag.py
[2024-08-31T22:25:46.377+0000] {processor.py:183} INFO - Processing /opt/airflow/dags/weather_etl_dag.py took 0.491 seconds
[2024-08-31T22:31:58.431+0000] {processor.py:161} INFO - Started process (PID=67) to work on /opt/airflow/dags/weather_etl_dag.py
[2024-08-31T22:31:58.453+0000] {processor.py:830} INFO - Processing file /opt/airflow/dags/weather_etl_dag.py for tasks to queue
[2024-08-31T22:31:58.475+0000] {logging_mixin.py:188} INFO - [2024-08-31T22:31:58.475+0000] {dagbag.py:545} INFO - Filling up the DagBag from /opt/airflow/dags/weather_etl_dag.py
[2024-08-31T22:31:58.579+0000] {logging_mixin.py:188} INFO - [2024-08-31T22:31:58.573+0000] {dagbag.py:355} ERROR - Failed to import: /opt/airflow/dags/weather_etl_dag.py
Traceback (most recent call last):
  File "/home/airflow/.local/lib/python3.12/site-packages/airflow/models/dagbag.py", line 351, in parse
    loader.exec_module(new_module)
  File "<frozen importlib._bootstrap_external>", line 995, in exec_module
  File "<frozen importlib._bootstrap>", line 488, in _call_with_frames_removed
  File "/opt/airflow/dags/weather_etl_dag.py", line 5, in <module>
    from weather_etl import get_municipios, fetch_weather_data, translate_and_clean_data
ModuleNotFoundError: No module named 'weather_etl'
[2024-08-31T22:31:58.580+0000] {processor.py:842} WARNING - No viable dags retrieved from /opt/airflow/dags/weather_etl_dag.py
[2024-08-31T22:31:59.026+0000] {processor.py:183} INFO - Processing /opt/airflow/dags/weather_etl_dag.py took 0.601 seconds
