[2024-08-30T00:00:30.963+0000] {local_task_job_runner.py:120} INFO - ::group::Pre task execution logs
[2024-08-30T00:00:30.983+0000] {taskinstance.py:2076} INFO - Dependencies all met for dep_context=non-requeueable deps ti=<TaskInstance: weather_etl_dag.get_municipios scheduled__2024-08-29T00:00:00+00:00 [queued]>
[2024-08-30T00:00:30.990+0000] {taskinstance.py:2076} INFO - Dependencies all met for dep_context=requeueable deps ti=<TaskInstance: weather_etl_dag.get_municipios scheduled__2024-08-29T00:00:00+00:00 [queued]>
[2024-08-30T00:00:30.991+0000] {taskinstance.py:2306} INFO - Starting attempt 1 of 2
[2024-08-30T00:00:31.161+0000] {taskinstance.py:2330} INFO - Executing <Task(PythonOperator): get_municipios> on 2024-08-29 00:00:00+00:00
[2024-08-30T00:00:31.165+0000] {warnings.py:112} WARNING - /home/***/.local/lib/python3.12/site-packages/***/task/task_runner/standard_task_runner.py:62: DeprecationWarning: This process (pid=610) is multi-threaded, use of fork() may lead to deadlocks in the child.
  pid = os.fork()

[2024-08-30T00:00:31.168+0000] {standard_task_runner.py:64} INFO - Started process 612 to run task
[2024-08-30T00:00:31.167+0000] {standard_task_runner.py:90} INFO - Running: ['***', 'tasks', 'run', 'weather_etl_dag', 'get_municipios', 'scheduled__2024-08-29T00:00:00+00:00', '--job-id', '413', '--raw', '--subdir', 'DAGS_FOLDER/weather_etl_dag.py', '--cfg-path', '/tmp/tmpz93e0qcx']
[2024-08-30T00:00:31.169+0000] {standard_task_runner.py:91} INFO - Job 413: Subtask get_municipios
[2024-08-30T00:00:31.251+0000] {task_command.py:426} INFO - Running <TaskInstance: weather_etl_dag.get_municipios scheduled__2024-08-29T00:00:00+00:00 [running]> on host b7290fbe53d7
[2024-08-30T00:00:31.437+0000] {taskinstance.py:2648} INFO - Exporting env vars: AIRFLOW_CTX_DAG_OWNER='***' AIRFLOW_CTX_DAG_ID='weather_etl_dag' AIRFLOW_CTX_TASK_ID='get_municipios' AIRFLOW_CTX_EXECUTION_DATE='2024-08-29T00:00:00+00:00' AIRFLOW_CTX_TRY_NUMBER='1' AIRFLOW_CTX_DAG_RUN_ID='scheduled__2024-08-29T00:00:00+00:00'
[2024-08-30T00:00:31.438+0000] {taskinstance.py:430} INFO - ::endgroup::
[2024-08-30T00:00:32.038+0000] {logging_mixin.py:188} INFO - Conexi√≥n establecida con Redshift.
[2024-08-30T00:00:32.039+0000] {logging_mixin.py:188} INFO - Ejecutando la consulta SQL...
[2024-08-30T00:00:32.047+0000] {warnings.py:112} WARNING - /opt/***/dags/weather_etl_dag.py:82: UserWarning: pandas only supports SQLAlchemy connectable (engine/connection) or database string URI or sqlite3 DBAPI2 connection. Other DBAPI2 objects are not tested. Please consider using SQLAlchemy.
  df_municipios = pd.read_sql_query(query, conn)

[2024-08-30T00:00:32.192+0000] {logging_mixin.py:188} INFO - Consulta ejecutada, numero de registros obtenidos:18
[2024-08-30T00:00:32.192+0000] {logging_mixin.py:188} INFO - conexion a redshift cerrada
[2024-08-30T00:00:32.262+0000] {python.py:237} INFO - Done. Returned value was: None
[2024-08-30T00:00:32.262+0000] {taskinstance.py:441} INFO - ::group::Post task execution logs
[2024-08-30T00:00:32.270+0000] {taskinstance.py:1206} INFO - Marking task as SUCCESS. dag_id=weather_etl_dag, task_id=get_municipios, run_id=scheduled__2024-08-29T00:00:00+00:00, execution_date=20240829T000000, start_date=20240830T000030, end_date=20240830T000032
[2024-08-30T00:00:32.351+0000] {local_task_job_runner.py:243} INFO - Task exited with return code 0
[2024-08-30T00:00:32.372+0000] {taskinstance.py:3503} INFO - 1 downstream tasks scheduled from follow-on schedule check
[2024-08-30T00:00:32.407+0000] {local_task_job_runner.py:222} INFO - ::endgroup::
[2024-09-04T23:59:50.539+0000] {local_task_job_runner.py:123} INFO - ::group::Pre task execution logs
[2024-09-04T23:59:50.680+0000] {taskinstance.py:2603} INFO - Dependencies all met for dep_context=non-requeueable deps ti=<TaskInstance: weather_etl_dag.get_municipios scheduled__2024-08-29T00:00:00+00:00 [queued]>
[2024-09-04T23:59:50.705+0000] {taskinstance.py:2603} INFO - Dependencies all met for dep_context=requeueable deps ti=<TaskInstance: weather_etl_dag.get_municipios scheduled__2024-08-29T00:00:00+00:00 [queued]>
[2024-09-04T23:59:50.708+0000] {taskinstance.py:2856} INFO - Starting attempt 1 of 2
[2024-09-04T23:59:50.862+0000] {taskinstance.py:2879} INFO - Executing <Task(PythonOperator): get_municipios> on 2024-08-29 00:00:00+00:00
[2024-09-04T23:59:50.870+0000] {warnings.py:112} WARNING - /usr/local/lib/python3.12/site-packages/***/task/task_runner/standard_task_runner.py:70: DeprecationWarning: This process (pid=279) is multi-threaded, use of fork() may lead to deadlocks in the child.
  pid = os.fork()

[2024-09-04T23:59:50.874+0000] {standard_task_runner.py:72} INFO - Started process 288 to run task
[2024-09-04T23:59:50.881+0000] {standard_task_runner.py:104} INFO - Running: ['***', 'tasks', 'run', 'weather_etl_dag', 'get_municipios', 'scheduled__2024-08-29T00:00:00+00:00', '--job-id', '49', '--raw', '--subdir', 'DAGS_FOLDER/weather_etl_dag.py', '--cfg-path', '/tmp/tmpgtbjh6pt']
[2024-09-04T23:59:50.883+0000] {standard_task_runner.py:105} INFO - Job 49: Subtask get_municipios
[2024-09-04T23:59:51.114+0000] {task_command.py:467} INFO - Running <TaskInstance: weather_etl_dag.get_municipios scheduled__2024-08-29T00:00:00+00:00 [running]> on host f3059b547e1e
[2024-09-04T23:59:51.594+0000] {taskinstance.py:3122} INFO - Exporting env vars: AIRFLOW_CTX_DAG_OWNER='***' AIRFLOW_CTX_DAG_ID='weather_etl_dag' AIRFLOW_CTX_TASK_ID='get_municipios' AIRFLOW_CTX_EXECUTION_DATE='2024-08-29T00:00:00+00:00' AIRFLOW_CTX_TRY_NUMBER='1' AIRFLOW_CTX_DAG_RUN_ID='scheduled__2024-08-29T00:00:00+00:00'
[2024-09-04T23:59:51.600+0000] {taskinstance.py:731} INFO - ::endgroup::
[2024-09-04T23:59:51.720+0000] {taskinstance.py:3301} ERROR - Task failed with exception
Traceback (most recent call last):
  File "/usr/local/lib/python3.12/site-packages/airflow/models/taskinstance.py", line 767, in _execute_task
    result = _execute_callable(context=context, **execute_callable_kwargs)
             ^^^^^^^^^^^^^^^^^^^^^^^^^^^^^^^^^^^^^^^^^^^^^^^^^^^^^^^^^^^^^
  File "/usr/local/lib/python3.12/site-packages/airflow/models/taskinstance.py", line 733, in _execute_callable
    return ExecutionCallableRunner(
           ^^^^^^^^^^^^^^^^^^^^^^^^
  File "/usr/local/lib/python3.12/site-packages/airflow/utils/operator_helpers.py", line 252, in run
    return self.func(*args, **kwargs)
           ^^^^^^^^^^^^^^^^^^^^^^^^^^
  File "/usr/local/lib/python3.12/site-packages/airflow/models/baseoperator.py", line 406, in wrapper
    return func(self, *args, **kwargs)
           ^^^^^^^^^^^^^^^^^^^^^^^^^^^
  File "/usr/local/lib/python3.12/site-packages/airflow/operators/python.py", line 238, in execute
    return_value = self.execute_callable()
                   ^^^^^^^^^^^^^^^^^^^^^^^
  File "/usr/local/lib/python3.12/site-packages/airflow/operators/python.py", line 256, in execute_callable
    return runner.run(*self.op_args, **self.op_kwargs)
           ^^^^^^^^^^^^^^^^^^^^^^^^^^^^^^^^^^^^^^^^^^^
  File "/usr/local/lib/python3.12/site-packages/airflow/utils/operator_helpers.py", line 252, in run
    return self.func(*args, **kwargs)
           ^^^^^^^^^^^^^^^^^^^^^^^^^^
  File "/root/airflow/dags/weather_etl.py", line 11, in get_municipios
    r_user = Variable.get("r_user")
             ^^^^^^^^^^^^^^^^^^^^^^
  File "/usr/local/lib/python3.12/site-packages/airflow/models/variable.py", line 145, in get
    raise KeyError(f"Variable {key} does not exist")
KeyError: 'Variable r_user does not exist'
[2024-09-04T23:59:51.826+0000] {taskinstance.py:1225} INFO - Marking task as UP_FOR_RETRY. dag_id=weather_etl_dag, task_id=get_municipios, run_id=scheduled__2024-08-29T00:00:00+00:00, execution_date=20240829T000000, start_date=20240904T235950, end_date=20240904T235951
[2024-09-04T23:59:52.395+0000] {taskinstance.py:340} INFO - ::group::Post task execution logs
[2024-09-04T23:59:52.400+0000] {standard_task_runner.py:124} ERROR - Failed to execute job 49 for task get_municipios ('Variable r_user does not exist'; 288)
Traceback (most recent call last):
  File "/usr/local/lib/python3.12/site-packages/airflow/task/task_runner/standard_task_runner.py", line 117, in _start_by_fork
    ret = args.func(args, dag=self.dag)
          ^^^^^^^^^^^^^^^^^^^^^^^^^^^^^
  File "/usr/local/lib/python3.12/site-packages/airflow/cli/cli_config.py", line 49, in command
    return func(*args, **kwargs)
           ^^^^^^^^^^^^^^^^^^^^^
  File "/usr/local/lib/python3.12/site-packages/airflow/utils/cli.py", line 115, in wrapper
    return f(*args, **kwargs)
           ^^^^^^^^^^^^^^^^^^
  File "/usr/local/lib/python3.12/site-packages/airflow/cli/commands/task_command.py", line 483, in task_run
    task_return_code = _run_task_by_selected_method(args, _dag, ti)
                       ^^^^^^^^^^^^^^^^^^^^^^^^^^^^^^^^^^^^^^^^^^^^
  File "/usr/local/lib/python3.12/site-packages/airflow/cli/commands/task_command.py", line 256, in _run_task_by_selected_method
    return _run_raw_task(args, ti)
           ^^^^^^^^^^^^^^^^^^^^^^^
  File "/usr/local/lib/python3.12/site-packages/airflow/cli/commands/task_command.py", line 341, in _run_raw_task
    return ti._run_raw_task(
           ^^^^^^^^^^^^^^^^^
  File "/usr/local/lib/python3.12/site-packages/airflow/utils/session.py", line 97, in wrapper
    return func(*args, session=session, **kwargs)
           ^^^^^^^^^^^^^^^^^^^^^^^^^^^^^^^^^^^^^^
  File "/usr/local/lib/python3.12/site-packages/airflow/models/taskinstance.py", line 2995, in _run_raw_task
    return _run_raw_task(
           ^^^^^^^^^^^^^^
  File "/usr/local/lib/python3.12/site-packages/airflow/models/taskinstance.py", line 273, in _run_raw_task
    TaskInstance._execute_task_with_callbacks(
  File "/usr/local/lib/python3.12/site-packages/airflow/models/taskinstance.py", line 3149, in _execute_task_with_callbacks
    result = self._execute_task(context, task_orig)
             ^^^^^^^^^^^^^^^^^^^^^^^^^^^^^^^^^^^^^^
  File "/usr/local/lib/python3.12/site-packages/airflow/models/taskinstance.py", line 3173, in _execute_task
    return _execute_task(self, context, task_orig)
           ^^^^^^^^^^^^^^^^^^^^^^^^^^^^^^^^^^^^^^^
  File "/usr/local/lib/python3.12/site-packages/airflow/models/taskinstance.py", line 767, in _execute_task
    result = _execute_callable(context=context, **execute_callable_kwargs)
             ^^^^^^^^^^^^^^^^^^^^^^^^^^^^^^^^^^^^^^^^^^^^^^^^^^^^^^^^^^^^^
  File "/usr/local/lib/python3.12/site-packages/airflow/models/taskinstance.py", line 733, in _execute_callable
    return ExecutionCallableRunner(
           ^^^^^^^^^^^^^^^^^^^^^^^^
  File "/usr/local/lib/python3.12/site-packages/airflow/utils/operator_helpers.py", line 252, in run
    return self.func(*args, **kwargs)
           ^^^^^^^^^^^^^^^^^^^^^^^^^^
  File "/usr/local/lib/python3.12/site-packages/airflow/models/baseoperator.py", line 406, in wrapper
    return func(self, *args, **kwargs)
           ^^^^^^^^^^^^^^^^^^^^^^^^^^^
  File "/usr/local/lib/python3.12/site-packages/airflow/operators/python.py", line 238, in execute
    return_value = self.execute_callable()
                   ^^^^^^^^^^^^^^^^^^^^^^^
  File "/usr/local/lib/python3.12/site-packages/airflow/operators/python.py", line 256, in execute_callable
    return runner.run(*self.op_args, **self.op_kwargs)
           ^^^^^^^^^^^^^^^^^^^^^^^^^^^^^^^^^^^^^^^^^^^
  File "/usr/local/lib/python3.12/site-packages/airflow/utils/operator_helpers.py", line 252, in run
    return self.func(*args, **kwargs)
           ^^^^^^^^^^^^^^^^^^^^^^^^^^
  File "/root/airflow/dags/weather_etl.py", line 11, in get_municipios
    r_user = Variable.get("r_user")
             ^^^^^^^^^^^^^^^^^^^^^^
  File "/usr/local/lib/python3.12/site-packages/airflow/models/variable.py", line 145, in get
    raise KeyError(f"Variable {key} does not exist")
KeyError: 'Variable r_user does not exist'
[2024-09-04T23:59:52.430+0000] {local_task_job_runner.py:261} INFO - Task exited with return code 1
[2024-09-04T23:59:52.545+0000] {taskinstance.py:3891} INFO - 0 downstream tasks scheduled from follow-on schedule check
[2024-09-04T23:59:52.622+0000] {local_task_job_runner.py:240} INFO - ::endgroup::
[2024-09-05T23:41:09.562+0000] {local_task_job_runner.py:123} INFO - ::group::Pre task execution logs
[2024-09-05T23:41:09.841+0000] {taskinstance.py:2603} INFO - Dependencies all met for dep_context=non-requeueable deps ti=<TaskInstance: weather_etl_dag.get_municipios scheduled__2024-08-29T00:00:00+00:00 [queued]>
[2024-09-05T23:41:10.100+0000] {taskinstance.py:2603} INFO - Dependencies all met for dep_context=requeueable deps ti=<TaskInstance: weather_etl_dag.get_municipios scheduled__2024-08-29T00:00:00+00:00 [queued]>
[2024-09-05T23:41:10.110+0000] {taskinstance.py:2856} INFO - Starting attempt 1 of 2
[2024-09-05T23:41:10.405+0000] {taskinstance.py:2879} INFO - Executing <Task(PythonOperator): get_municipios> on 2024-08-29 00:00:00+00:00
[2024-09-05T23:41:10.409+0000] {warnings.py:112} WARNING - /usr/local/lib/python3.12/site-packages/***/task/task_runner/standard_task_runner.py:70: DeprecationWarning: This process (pid=135) is multi-threaded, use of fork() may lead to deadlocks in the child.
  pid = os.fork()

[2024-09-05T23:41:10.411+0000] {standard_task_runner.py:72} INFO - Started process 152 to run task
[2024-09-05T23:41:10.412+0000] {standard_task_runner.py:104} INFO - Running: ['***', 'tasks', 'run', 'weather_etl_dag', 'get_municipios', 'scheduled__2024-08-29T00:00:00+00:00', '--job-id', '139', '--raw', '--subdir', 'DAGS_FOLDER/weather_etl_dag.py', '--cfg-path', '/tmp/tmpmj_i2nlh']
[2024-09-05T23:41:10.414+0000] {standard_task_runner.py:105} INFO - Job 139: Subtask get_municipios
[2024-09-05T23:41:10.545+0000] {task_command.py:467} INFO - Running <TaskInstance: weather_etl_dag.get_municipios scheduled__2024-08-29T00:00:00+00:00 [running]> on host da9f5d3bcb59
[2024-09-05T23:41:15.939+0000] {taskinstance.py:3122} INFO - Exporting env vars: AIRFLOW_CTX_DAG_OWNER='***' AIRFLOW_CTX_DAG_ID='weather_etl_dag' AIRFLOW_CTX_TASK_ID='get_municipios' AIRFLOW_CTX_EXECUTION_DATE='2024-08-29T00:00:00+00:00' AIRFLOW_CTX_TRY_NUMBER='1' AIRFLOW_CTX_DAG_RUN_ID='scheduled__2024-08-29T00:00:00+00:00'
[2024-09-05T23:41:15.940+0000] {taskinstance.py:731} INFO - ::endgroup::
[2024-09-05T23:41:16.540+0000] {warnings.py:112} WARNING - /root/***/dags/weather_etl.py:25: UserWarning: pandas only supports SQLAlchemy connectable (engine/connection) or database string URI or sqlite3 DBAPI2 connection. Other DBAPI2 objects are not tested. Please consider using SQLAlchemy.
  df_municipios = pd.read_sql_query(query, conn)

[2024-09-05T23:41:17.607+0000] {python.py:240} INFO - Done. Returned value was: None
[2024-09-05T23:41:17.618+0000] {taskinstance.py:340} INFO - ::group::Post task execution logs
[2024-09-05T23:41:17.618+0000] {taskinstance.py:352} INFO - Marking task as SUCCESS. dag_id=weather_etl_dag, task_id=get_municipios, run_id=scheduled__2024-08-29T00:00:00+00:00, execution_date=20240829T000000, start_date=20240905T234109, end_date=20240905T234117
[2024-09-05T23:41:17.808+0000] {local_task_job_runner.py:261} INFO - Task exited with return code 0
[2024-09-05T23:41:23.832+0000] {standard_task_runner.py:217} INFO - Process not found (most likely exited), stop collecting metrics
[2024-09-05T23:41:23.844+0000] {taskinstance.py:3891} INFO - 1 downstream tasks scheduled from follow-on schedule check
[2024-09-05T23:41:23.928+0000] {local_task_job_runner.py:240} INFO - ::endgroup::
