[2024-09-04T23:59:00.816+0000] {local_task_job_runner.py:123} INFO - ::group::Pre task execution logs
[2024-09-04T23:59:00.858+0000] {taskinstance.py:2603} INFO - Dependencies all met for dep_context=non-requeueable deps ti=<TaskInstance: weather_etl_dag.get_municipios scheduled__2024-08-11T00:00:00+00:00 [queued]>
[2024-09-04T23:59:00.869+0000] {taskinstance.py:2603} INFO - Dependencies all met for dep_context=requeueable deps ti=<TaskInstance: weather_etl_dag.get_municipios scheduled__2024-08-11T00:00:00+00:00 [queued]>
[2024-09-04T23:59:00.986+0000] {taskinstance.py:2856} INFO - Starting attempt 2 of 2
[2024-09-04T23:59:01.067+0000] {taskinstance.py:2879} INFO - Executing <Task(PythonOperator): get_municipios> on 2024-08-11 00:00:00+00:00
[2024-09-04T23:59:01.072+0000] {warnings.py:112} WARNING - /usr/local/lib/python3.12/site-packages/***/task/task_runner/standard_task_runner.py:70: DeprecationWarning: This process (pid=216) is multi-threaded, use of fork() may lead to deadlocks in the child.
  pid = os.fork()

[2024-09-04T23:59:01.084+0000] {standard_task_runner.py:72} INFO - Started process 217 to run task
[2024-09-04T23:59:01.080+0000] {standard_task_runner.py:104} INFO - Running: ['***', 'tasks', 'run', 'weather_etl_dag', 'get_municipios', 'scheduled__2024-08-11T00:00:00+00:00', '--job-id', '31', '--raw', '--subdir', 'DAGS_FOLDER/weather_etl_dag.py', '--cfg-path', '/tmp/tmprw_wsst8']
[2024-09-04T23:59:01.090+0000] {standard_task_runner.py:105} INFO - Job 31: Subtask get_municipios
[2024-09-04T23:59:01.474+0000] {task_command.py:467} INFO - Running <TaskInstance: weather_etl_dag.get_municipios scheduled__2024-08-11T00:00:00+00:00 [running]> on host f3059b547e1e
[2024-09-04T23:59:02.844+0000] {taskinstance.py:3122} INFO - Exporting env vars: AIRFLOW_CTX_DAG_OWNER='***' AIRFLOW_CTX_DAG_ID='weather_etl_dag' AIRFLOW_CTX_TASK_ID='get_municipios' AIRFLOW_CTX_EXECUTION_DATE='2024-08-11T00:00:00+00:00' AIRFLOW_CTX_TRY_NUMBER='2' AIRFLOW_CTX_DAG_RUN_ID='scheduled__2024-08-11T00:00:00+00:00'
[2024-09-04T23:59:02.860+0000] {taskinstance.py:731} INFO - ::endgroup::
[2024-09-04T23:59:03.160+0000] {taskinstance.py:3301} ERROR - Task failed with exception
Traceback (most recent call last):
  File "/usr/local/lib/python3.12/site-packages/airflow/models/taskinstance.py", line 767, in _execute_task
    result = _execute_callable(context=context, **execute_callable_kwargs)
             ^^^^^^^^^^^^^^^^^^^^^^^^^^^^^^^^^^^^^^^^^^^^^^^^^^^^^^^^^^^^^
  File "/usr/local/lib/python3.12/site-packages/airflow/models/taskinstance.py", line 733, in _execute_callable
    return ExecutionCallableRunner(
           ^^^^^^^^^^^^^^^^^^^^^^^^
  File "/usr/local/lib/python3.12/site-packages/airflow/utils/operator_helpers.py", line 252, in run
    return self.func(*args, **kwargs)
           ^^^^^^^^^^^^^^^^^^^^^^^^^^
  File "/usr/local/lib/python3.12/site-packages/airflow/models/baseoperator.py", line 406, in wrapper
    return func(self, *args, **kwargs)
           ^^^^^^^^^^^^^^^^^^^^^^^^^^^
  File "/usr/local/lib/python3.12/site-packages/airflow/operators/python.py", line 238, in execute
    return_value = self.execute_callable()
                   ^^^^^^^^^^^^^^^^^^^^^^^
  File "/usr/local/lib/python3.12/site-packages/airflow/operators/python.py", line 256, in execute_callable
    return runner.run(*self.op_args, **self.op_kwargs)
           ^^^^^^^^^^^^^^^^^^^^^^^^^^^^^^^^^^^^^^^^^^^
  File "/usr/local/lib/python3.12/site-packages/airflow/utils/operator_helpers.py", line 252, in run
    return self.func(*args, **kwargs)
           ^^^^^^^^^^^^^^^^^^^^^^^^^^
  File "/root/airflow/dags/weather_etl.py", line 11, in get_municipios
    r_user = Variable.get("r_user")
             ^^^^^^^^^^^^^^^^^^^^^^
  File "/usr/local/lib/python3.12/site-packages/airflow/models/variable.py", line 145, in get
    raise KeyError(f"Variable {key} does not exist")
KeyError: 'Variable r_user does not exist'
[2024-09-04T23:59:03.293+0000] {taskinstance.py:1225} INFO - Marking task as FAILED. dag_id=weather_etl_dag, task_id=get_municipios, run_id=scheduled__2024-08-11T00:00:00+00:00, execution_date=20240811T000000, start_date=20240904T235900, end_date=20240904T235903
[2024-09-04T23:59:03.908+0000] {taskinstance.py:340} INFO - ::group::Post task execution logs
[2024-09-04T23:59:03.914+0000] {standard_task_runner.py:124} ERROR - Failed to execute job 31 for task get_municipios ('Variable r_user does not exist'; 217)
Traceback (most recent call last):
  File "/usr/local/lib/python3.12/site-packages/airflow/task/task_runner/standard_task_runner.py", line 117, in _start_by_fork
    ret = args.func(args, dag=self.dag)
          ^^^^^^^^^^^^^^^^^^^^^^^^^^^^^
  File "/usr/local/lib/python3.12/site-packages/airflow/cli/cli_config.py", line 49, in command
    return func(*args, **kwargs)
           ^^^^^^^^^^^^^^^^^^^^^
  File "/usr/local/lib/python3.12/site-packages/airflow/utils/cli.py", line 115, in wrapper
    return f(*args, **kwargs)
           ^^^^^^^^^^^^^^^^^^
  File "/usr/local/lib/python3.12/site-packages/airflow/cli/commands/task_command.py", line 483, in task_run
    task_return_code = _run_task_by_selected_method(args, _dag, ti)
                       ^^^^^^^^^^^^^^^^^^^^^^^^^^^^^^^^^^^^^^^^^^^^
  File "/usr/local/lib/python3.12/site-packages/airflow/cli/commands/task_command.py", line 256, in _run_task_by_selected_method
    return _run_raw_task(args, ti)
           ^^^^^^^^^^^^^^^^^^^^^^^
  File "/usr/local/lib/python3.12/site-packages/airflow/cli/commands/task_command.py", line 341, in _run_raw_task
    return ti._run_raw_task(
           ^^^^^^^^^^^^^^^^^
  File "/usr/local/lib/python3.12/site-packages/airflow/utils/session.py", line 97, in wrapper
    return func(*args, session=session, **kwargs)
           ^^^^^^^^^^^^^^^^^^^^^^^^^^^^^^^^^^^^^^
  File "/usr/local/lib/python3.12/site-packages/airflow/models/taskinstance.py", line 2995, in _run_raw_task
    return _run_raw_task(
           ^^^^^^^^^^^^^^
  File "/usr/local/lib/python3.12/site-packages/airflow/models/taskinstance.py", line 273, in _run_raw_task
    TaskInstance._execute_task_with_callbacks(
  File "/usr/local/lib/python3.12/site-packages/airflow/models/taskinstance.py", line 3149, in _execute_task_with_callbacks
    result = self._execute_task(context, task_orig)
             ^^^^^^^^^^^^^^^^^^^^^^^^^^^^^^^^^^^^^^
  File "/usr/local/lib/python3.12/site-packages/airflow/models/taskinstance.py", line 3173, in _execute_task
    return _execute_task(self, context, task_orig)
           ^^^^^^^^^^^^^^^^^^^^^^^^^^^^^^^^^^^^^^^
  File "/usr/local/lib/python3.12/site-packages/airflow/models/taskinstance.py", line 767, in _execute_task
    result = _execute_callable(context=context, **execute_callable_kwargs)
             ^^^^^^^^^^^^^^^^^^^^^^^^^^^^^^^^^^^^^^^^^^^^^^^^^^^^^^^^^^^^^
  File "/usr/local/lib/python3.12/site-packages/airflow/models/taskinstance.py", line 733, in _execute_callable
    return ExecutionCallableRunner(
           ^^^^^^^^^^^^^^^^^^^^^^^^
  File "/usr/local/lib/python3.12/site-packages/airflow/utils/operator_helpers.py", line 252, in run
    return self.func(*args, **kwargs)
           ^^^^^^^^^^^^^^^^^^^^^^^^^^
  File "/usr/local/lib/python3.12/site-packages/airflow/models/baseoperator.py", line 406, in wrapper
    return func(self, *args, **kwargs)
           ^^^^^^^^^^^^^^^^^^^^^^^^^^^
  File "/usr/local/lib/python3.12/site-packages/airflow/operators/python.py", line 238, in execute
    return_value = self.execute_callable()
                   ^^^^^^^^^^^^^^^^^^^^^^^
  File "/usr/local/lib/python3.12/site-packages/airflow/operators/python.py", line 256, in execute_callable
    return runner.run(*self.op_args, **self.op_kwargs)
           ^^^^^^^^^^^^^^^^^^^^^^^^^^^^^^^^^^^^^^^^^^^
  File "/usr/local/lib/python3.12/site-packages/airflow/utils/operator_helpers.py", line 252, in run
    return self.func(*args, **kwargs)
           ^^^^^^^^^^^^^^^^^^^^^^^^^^
  File "/root/airflow/dags/weather_etl.py", line 11, in get_municipios
    r_user = Variable.get("r_user")
             ^^^^^^^^^^^^^^^^^^^^^^
  File "/usr/local/lib/python3.12/site-packages/airflow/models/variable.py", line 145, in get
    raise KeyError(f"Variable {key} does not exist")
KeyError: 'Variable r_user does not exist'
[2024-09-04T23:59:04.049+0000] {local_task_job_runner.py:261} INFO - Task exited with return code 1
[2024-09-04T23:59:04.259+0000] {taskinstance.py:3891} INFO - 0 downstream tasks scheduled from follow-on schedule check
[2024-09-04T23:59:04.330+0000] {local_task_job_runner.py:240} INFO - ::endgroup::
[2024-09-05T00:33:57.904+0000] {local_task_job_runner.py:123} INFO - ::group::Pre task execution logs
[2024-09-05T00:33:58.051+0000] {taskinstance.py:2603} INFO - Dependencies all met for dep_context=non-requeueable deps ti=<TaskInstance: weather_etl_dag.get_municipios scheduled__2024-08-11T00:00:00+00:00 [queued]>
[2024-09-05T00:33:58.082+0000] {taskinstance.py:2603} INFO - Dependencies all met for dep_context=requeueable deps ti=<TaskInstance: weather_etl_dag.get_municipios scheduled__2024-08-11T00:00:00+00:00 [queued]>
[2024-09-05T00:33:58.087+0000] {taskinstance.py:2856} INFO - Starting attempt 2 of 2
[2024-09-05T00:33:58.181+0000] {taskinstance.py:2879} INFO - Executing <Task(PythonOperator): get_municipios> on 2024-08-11 00:00:00+00:00
[2024-09-05T00:33:58.293+0000] {warnings.py:112} WARNING - /usr/local/lib/python3.12/site-packages/***/task/task_runner/standard_task_runner.py:70: DeprecationWarning: This process (pid=261) is multi-threaded, use of fork() may lead to deadlocks in the child.
  pid = os.fork()

[2024-09-05T00:33:58.304+0000] {standard_task_runner.py:72} INFO - Started process 272 to run task
[2024-09-05T00:33:58.268+0000] {standard_task_runner.py:104} INFO - Running: ['***', 'tasks', 'run', 'weather_etl_dag', 'get_municipios', 'scheduled__2024-08-11T00:00:00+00:00', '--job-id', '34', '--raw', '--subdir', 'DAGS_FOLDER/weather_etl_dag.py', '--cfg-path', '/tmp/tmp9s59uapq']
[2024-09-05T00:33:58.306+0000] {standard_task_runner.py:105} INFO - Job 34: Subtask get_municipios
[2024-09-05T00:33:58.931+0000] {task_command.py:467} INFO - Running <TaskInstance: weather_etl_dag.get_municipios scheduled__2024-08-11T00:00:00+00:00 [running]> on host b778581f4b0f
[2024-09-05T00:34:00.820+0000] {taskinstance.py:3122} INFO - Exporting env vars: AIRFLOW_CTX_DAG_OWNER='***' AIRFLOW_CTX_DAG_ID='weather_etl_dag' AIRFLOW_CTX_TASK_ID='get_municipios' AIRFLOW_CTX_EXECUTION_DATE='2024-08-11T00:00:00+00:00' AIRFLOW_CTX_TRY_NUMBER='2' AIRFLOW_CTX_DAG_RUN_ID='scheduled__2024-08-11T00:00:00+00:00'
[2024-09-05T00:34:00.822+0000] {taskinstance.py:731} INFO - ::endgroup::
[2024-09-05T00:34:01.746+0000] {logging_mixin.py:190} INFO - Conexión establecida con Redshift.
[2024-09-05T00:34:01.749+0000] {logging_mixin.py:190} INFO - Ejecutando la consulta SQL...
[2024-09-05T00:34:01.783+0000] {warnings.py:112} WARNING - /root/***/dags/weather_etl.py:29: UserWarning: pandas only supports SQLAlchemy connectable (engine/connection) or database string URI or sqlite3 DBAPI2 connection. Other DBAPI2 objects are not tested. Please consider using SQLAlchemy.
  df_municipios = pd.read_sql_query(query, conn)

[2024-09-05T00:34:01.952+0000] {logging_mixin.py:190} INFO - Consulta ejecutada, número de registros obtenidos: 18
[2024-09-05T00:34:01.970+0000] {logging_mixin.py:190} INFO - Conexión a Redshift cerrada
[2024-09-05T00:34:02.163+0000] {python.py:240} INFO - Done. Returned value was: None
[2024-09-05T00:34:02.209+0000] {taskinstance.py:340} INFO - ::group::Post task execution logs
[2024-09-05T00:34:02.210+0000] {taskinstance.py:352} INFO - Marking task as SUCCESS. dag_id=weather_etl_dag, task_id=get_municipios, run_id=scheduled__2024-08-11T00:00:00+00:00, execution_date=20240811T000000, start_date=20240905T003358, end_date=20240905T003402
[2024-09-05T00:34:02.441+0000] {local_task_job_runner.py:261} INFO - Task exited with return code 0
[2024-09-05T00:34:02.719+0000] {taskinstance.py:3891} INFO - 1 downstream tasks scheduled from follow-on schedule check
[2024-09-05T00:34:02.816+0000] {local_task_job_runner.py:240} INFO - ::endgroup::
