[2024-08-20T14:53:48.885+0000] {local_task_job_runner.py:120} INFO - ::group::Pre task execution logs
[2024-08-20T14:53:49.003+0000] {taskinstance.py:2076} INFO - Dependencies all met for dep_context=non-requeueable deps ti=<TaskInstance: weather_etl_dag.get_municipios scheduled__2024-08-19T00:00:00+00:00 [queued]>
[2024-08-20T14:53:49.049+0000] {taskinstance.py:2076} INFO - Dependencies all met for dep_context=requeueable deps ti=<TaskInstance: weather_etl_dag.get_municipios scheduled__2024-08-19T00:00:00+00:00 [queued]>
[2024-08-20T14:53:49.061+0000] {taskinstance.py:2306} INFO - Starting attempt 1 of 2
[2024-08-20T14:53:49.670+0000] {taskinstance.py:2330} INFO - Executing <Task(PythonOperator): get_municipios> on 2024-08-19 00:00:00+00:00
[2024-08-20T14:53:49.683+0000] {standard_task_runner.py:90} INFO - Running: ['***', 'tasks', 'run', 'weather_etl_dag', 'get_municipios', 'scheduled__2024-08-19T00:00:00+00:00', '--job-id', '223', '--raw', '--subdir', 'DAGS_FOLDER/weather_etl_dag.py', '--cfg-path', '/tmp/tmptdjoygj0']
[2024-08-20T14:53:49.694+0000] {standard_task_runner.py:91} INFO - Job 223: Subtask get_municipios
[2024-08-20T14:53:49.695+0000] {warnings.py:112} WARNING - /home/***/.local/lib/python3.12/site-packages/***/task/task_runner/standard_task_runner.py:62: DeprecationWarning: This process (pid=55) is multi-threaded, use of fork() may lead to deadlocks in the child.
  pid = os.fork()

[2024-08-20T14:53:49.701+0000] {standard_task_runner.py:64} INFO - Started process 64 to run task
[2024-08-20T14:53:50.141+0000] {task_command.py:426} INFO - Running <TaskInstance: weather_etl_dag.get_municipios scheduled__2024-08-19T00:00:00+00:00 [running]> on host b7290fbe53d7
[2024-08-20T14:53:51.165+0000] {taskinstance.py:2648} INFO - Exporting env vars: AIRFLOW_CTX_DAG_OWNER='***' AIRFLOW_CTX_DAG_ID='weather_etl_dag' AIRFLOW_CTX_TASK_ID='get_municipios' AIRFLOW_CTX_EXECUTION_DATE='2024-08-19T00:00:00+00:00' AIRFLOW_CTX_TRY_NUMBER='1' AIRFLOW_CTX_DAG_RUN_ID='scheduled__2024-08-19T00:00:00+00:00'
[2024-08-20T14:53:51.167+0000] {taskinstance.py:430} INFO - ::endgroup::
[2024-08-20T14:53:52.293+0000] {logging_mixin.py:188} INFO - Conexi√≥n establecida con Redshift.
[2024-08-20T14:53:52.294+0000] {logging_mixin.py:188} INFO - Ejecutando la consulta SQL...
[2024-08-20T14:53:52.525+0000] {warnings.py:112} WARNING - /opt/***/dags/weather_etl_dag.py:82: UserWarning: pandas only supports SQLAlchemy connectable (engine/connection) or database string URI or sqlite3 DBAPI2 connection. Other DBAPI2 objects are not tested. Please consider using SQLAlchemy.
  df_municipios = pd.read_sql_query(query, conn)

[2024-08-20T14:53:52.840+0000] {logging_mixin.py:188} INFO - Consulta ejecutada, numero de registros obtenidos:18
[2024-08-20T14:53:52.848+0000] {logging_mixin.py:188} INFO - conexion a redshift cerrada
[2024-08-20T14:53:54.164+0000] {python.py:237} INFO - Done. Returned value was: None
[2024-08-20T14:53:54.166+0000] {taskinstance.py:441} INFO - ::group::Post task execution logs
[2024-08-20T14:53:54.201+0000] {taskinstance.py:1206} INFO - Marking task as SUCCESS. dag_id=weather_etl_dag, task_id=get_municipios, run_id=scheduled__2024-08-19T00:00:00+00:00, execution_date=20240819T000000, start_date=20240820T145349, end_date=20240820T145354
[2024-08-20T14:53:54.484+0000] {local_task_job_runner.py:243} INFO - Task exited with return code 0
[2024-08-20T14:53:54.558+0000] {taskinstance.py:3503} INFO - 1 downstream tasks scheduled from follow-on schedule check
[2024-08-20T14:53:54.669+0000] {local_task_job_runner.py:222} INFO - ::endgroup::
[2024-09-04T23:59:27.872+0000] {local_task_job_runner.py:123} INFO - ::group::Pre task execution logs
[2024-09-04T23:59:27.967+0000] {taskinstance.py:2603} INFO - Dependencies all met for dep_context=non-requeueable deps ti=<TaskInstance: weather_etl_dag.get_municipios scheduled__2024-08-19T00:00:00+00:00 [queued]>
[2024-09-04T23:59:27.986+0000] {taskinstance.py:2603} INFO - Dependencies all met for dep_context=requeueable deps ti=<TaskInstance: weather_etl_dag.get_municipios scheduled__2024-08-19T00:00:00+00:00 [queued]>
[2024-09-04T23:59:27.986+0000] {taskinstance.py:2856} INFO - Starting attempt 1 of 2
[2024-09-04T23:59:28.050+0000] {taskinstance.py:2879} INFO - Executing <Task(PythonOperator): get_municipios> on 2024-08-19 00:00:00+00:00
[2024-09-04T23:59:28.059+0000] {warnings.py:112} WARNING - /usr/local/lib/python3.12/site-packages/***/task/task_runner/standard_task_runner.py:70: DeprecationWarning: This process (pid=249) is multi-threaded, use of fork() may lead to deadlocks in the child.
  pid = os.fork()

[2024-09-04T23:59:28.060+0000] {standard_task_runner.py:72} INFO - Started process 251 to run task
[2024-09-04T23:59:28.065+0000] {standard_task_runner.py:104} INFO - Running: ['***', 'tasks', 'run', 'weather_etl_dag', 'get_municipios', 'scheduled__2024-08-19T00:00:00+00:00', '--job-id', '39', '--raw', '--subdir', 'DAGS_FOLDER/weather_etl_dag.py', '--cfg-path', '/tmp/tmpp2c8kaxi']
[2024-09-04T23:59:28.067+0000] {standard_task_runner.py:105} INFO - Job 39: Subtask get_municipios
[2024-09-04T23:59:28.288+0000] {task_command.py:467} INFO - Running <TaskInstance: weather_etl_dag.get_municipios scheduled__2024-08-19T00:00:00+00:00 [running]> on host f3059b547e1e
[2024-09-04T23:59:28.635+0000] {taskinstance.py:3122} INFO - Exporting env vars: AIRFLOW_CTX_DAG_OWNER='***' AIRFLOW_CTX_DAG_ID='weather_etl_dag' AIRFLOW_CTX_TASK_ID='get_municipios' AIRFLOW_CTX_EXECUTION_DATE='2024-08-19T00:00:00+00:00' AIRFLOW_CTX_TRY_NUMBER='1' AIRFLOW_CTX_DAG_RUN_ID='scheduled__2024-08-19T00:00:00+00:00'
[2024-09-04T23:59:28.641+0000] {taskinstance.py:731} INFO - ::endgroup::
[2024-09-04T23:59:28.681+0000] {taskinstance.py:3301} ERROR - Task failed with exception
Traceback (most recent call last):
  File "/usr/local/lib/python3.12/site-packages/airflow/models/taskinstance.py", line 767, in _execute_task
    result = _execute_callable(context=context, **execute_callable_kwargs)
             ^^^^^^^^^^^^^^^^^^^^^^^^^^^^^^^^^^^^^^^^^^^^^^^^^^^^^^^^^^^^^
  File "/usr/local/lib/python3.12/site-packages/airflow/models/taskinstance.py", line 733, in _execute_callable
    return ExecutionCallableRunner(
           ^^^^^^^^^^^^^^^^^^^^^^^^
  File "/usr/local/lib/python3.12/site-packages/airflow/utils/operator_helpers.py", line 252, in run
    return self.func(*args, **kwargs)
           ^^^^^^^^^^^^^^^^^^^^^^^^^^
  File "/usr/local/lib/python3.12/site-packages/airflow/models/baseoperator.py", line 406, in wrapper
    return func(self, *args, **kwargs)
           ^^^^^^^^^^^^^^^^^^^^^^^^^^^
  File "/usr/local/lib/python3.12/site-packages/airflow/operators/python.py", line 238, in execute
    return_value = self.execute_callable()
                   ^^^^^^^^^^^^^^^^^^^^^^^
  File "/usr/local/lib/python3.12/site-packages/airflow/operators/python.py", line 256, in execute_callable
    return runner.run(*self.op_args, **self.op_kwargs)
           ^^^^^^^^^^^^^^^^^^^^^^^^^^^^^^^^^^^^^^^^^^^
  File "/usr/local/lib/python3.12/site-packages/airflow/utils/operator_helpers.py", line 252, in run
    return self.func(*args, **kwargs)
           ^^^^^^^^^^^^^^^^^^^^^^^^^^
  File "/root/airflow/dags/weather_etl.py", line 11, in get_municipios
    r_user = Variable.get("r_user")
             ^^^^^^^^^^^^^^^^^^^^^^
  File "/usr/local/lib/python3.12/site-packages/airflow/models/variable.py", line 145, in get
    raise KeyError(f"Variable {key} does not exist")
KeyError: 'Variable r_user does not exist'
[2024-09-04T23:59:28.703+0000] {taskinstance.py:1225} INFO - Marking task as UP_FOR_RETRY. dag_id=weather_etl_dag, task_id=get_municipios, run_id=scheduled__2024-08-19T00:00:00+00:00, execution_date=20240819T000000, start_date=20240904T235927, end_date=20240904T235928
[2024-09-04T23:59:29.095+0000] {taskinstance.py:340} INFO - ::group::Post task execution logs
[2024-09-04T23:59:29.096+0000] {standard_task_runner.py:124} ERROR - Failed to execute job 39 for task get_municipios ('Variable r_user does not exist'; 251)
Traceback (most recent call last):
  File "/usr/local/lib/python3.12/site-packages/airflow/task/task_runner/standard_task_runner.py", line 117, in _start_by_fork
    ret = args.func(args, dag=self.dag)
          ^^^^^^^^^^^^^^^^^^^^^^^^^^^^^
  File "/usr/local/lib/python3.12/site-packages/airflow/cli/cli_config.py", line 49, in command
    return func(*args, **kwargs)
           ^^^^^^^^^^^^^^^^^^^^^
  File "/usr/local/lib/python3.12/site-packages/airflow/utils/cli.py", line 115, in wrapper
    return f(*args, **kwargs)
           ^^^^^^^^^^^^^^^^^^
  File "/usr/local/lib/python3.12/site-packages/airflow/cli/commands/task_command.py", line 483, in task_run
    task_return_code = _run_task_by_selected_method(args, _dag, ti)
                       ^^^^^^^^^^^^^^^^^^^^^^^^^^^^^^^^^^^^^^^^^^^^
  File "/usr/local/lib/python3.12/site-packages/airflow/cli/commands/task_command.py", line 256, in _run_task_by_selected_method
    return _run_raw_task(args, ti)
           ^^^^^^^^^^^^^^^^^^^^^^^
  File "/usr/local/lib/python3.12/site-packages/airflow/cli/commands/task_command.py", line 341, in _run_raw_task
    return ti._run_raw_task(
           ^^^^^^^^^^^^^^^^^
  File "/usr/local/lib/python3.12/site-packages/airflow/utils/session.py", line 97, in wrapper
    return func(*args, session=session, **kwargs)
           ^^^^^^^^^^^^^^^^^^^^^^^^^^^^^^^^^^^^^^
  File "/usr/local/lib/python3.12/site-packages/airflow/models/taskinstance.py", line 2995, in _run_raw_task
    return _run_raw_task(
           ^^^^^^^^^^^^^^
  File "/usr/local/lib/python3.12/site-packages/airflow/models/taskinstance.py", line 273, in _run_raw_task
    TaskInstance._execute_task_with_callbacks(
  File "/usr/local/lib/python3.12/site-packages/airflow/models/taskinstance.py", line 3149, in _execute_task_with_callbacks
    result = self._execute_task(context, task_orig)
             ^^^^^^^^^^^^^^^^^^^^^^^^^^^^^^^^^^^^^^
  File "/usr/local/lib/python3.12/site-packages/airflow/models/taskinstance.py", line 3173, in _execute_task
    return _execute_task(self, context, task_orig)
           ^^^^^^^^^^^^^^^^^^^^^^^^^^^^^^^^^^^^^^^
  File "/usr/local/lib/python3.12/site-packages/airflow/models/taskinstance.py", line 767, in _execute_task
    result = _execute_callable(context=context, **execute_callable_kwargs)
             ^^^^^^^^^^^^^^^^^^^^^^^^^^^^^^^^^^^^^^^^^^^^^^^^^^^^^^^^^^^^^
  File "/usr/local/lib/python3.12/site-packages/airflow/models/taskinstance.py", line 733, in _execute_callable
    return ExecutionCallableRunner(
           ^^^^^^^^^^^^^^^^^^^^^^^^
  File "/usr/local/lib/python3.12/site-packages/airflow/utils/operator_helpers.py", line 252, in run
    return self.func(*args, **kwargs)
           ^^^^^^^^^^^^^^^^^^^^^^^^^^
  File "/usr/local/lib/python3.12/site-packages/airflow/models/baseoperator.py", line 406, in wrapper
    return func(self, *args, **kwargs)
           ^^^^^^^^^^^^^^^^^^^^^^^^^^^
  File "/usr/local/lib/python3.12/site-packages/airflow/operators/python.py", line 238, in execute
    return_value = self.execute_callable()
                   ^^^^^^^^^^^^^^^^^^^^^^^
  File "/usr/local/lib/python3.12/site-packages/airflow/operators/python.py", line 256, in execute_callable
    return runner.run(*self.op_args, **self.op_kwargs)
           ^^^^^^^^^^^^^^^^^^^^^^^^^^^^^^^^^^^^^^^^^^^
  File "/usr/local/lib/python3.12/site-packages/airflow/utils/operator_helpers.py", line 252, in run
    return self.func(*args, **kwargs)
           ^^^^^^^^^^^^^^^^^^^^^^^^^^
  File "/root/airflow/dags/weather_etl.py", line 11, in get_municipios
    r_user = Variable.get("r_user")
             ^^^^^^^^^^^^^^^^^^^^^^
  File "/usr/local/lib/python3.12/site-packages/airflow/models/variable.py", line 145, in get
    raise KeyError(f"Variable {key} does not exist")
KeyError: 'Variable r_user does not exist'
[2024-09-04T23:59:29.147+0000] {local_task_job_runner.py:261} INFO - Task exited with return code 1
[2024-09-04T23:59:29.182+0000] {taskinstance.py:3891} INFO - 0 downstream tasks scheduled from follow-on schedule check
[2024-09-04T23:59:29.599+0000] {local_task_job_runner.py:240} INFO - ::endgroup::
[2024-09-05T18:19:14.781+0000] {local_task_job_runner.py:123} INFO - ::group::Pre task execution logs
[2024-09-05T18:19:14.917+0000] {taskinstance.py:2603} INFO - Dependencies all met for dep_context=non-requeueable deps ti=<TaskInstance: weather_etl_dag.get_municipios scheduled__2024-08-19T00:00:00+00:00 [queued]>
[2024-09-05T18:19:14.950+0000] {taskinstance.py:2603} INFO - Dependencies all met for dep_context=requeueable deps ti=<TaskInstance: weather_etl_dag.get_municipios scheduled__2024-08-19T00:00:00+00:00 [queued]>
[2024-09-05T18:19:14.958+0000] {taskinstance.py:2856} INFO - Starting attempt 1 of 2
[2024-09-05T18:19:15.102+0000] {taskinstance.py:2879} INFO - Executing <Task(PythonOperator): get_municipios> on 2024-08-19 00:00:00+00:00
[2024-09-05T18:19:15.115+0000] {standard_task_runner.py:104} INFO - Running: ['***', 'tasks', 'run', 'weather_etl_dag', 'get_municipios', 'scheduled__2024-08-19T00:00:00+00:00', '--job-id', '112', '--raw', '--subdir', 'DAGS_FOLDER/weather_etl_dag.py', '--cfg-path', '/tmp/tmprqyv_z6g']
[2024-09-05T18:19:15.110+0000] {warnings.py:112} WARNING - /usr/local/lib/python3.12/site-packages/***/task/task_runner/standard_task_runner.py:70: DeprecationWarning: This process (pid=1140) is multi-threaded, use of fork() may lead to deadlocks in the child.
  pid = os.fork()

[2024-09-05T18:19:15.157+0000] {standard_task_runner.py:72} INFO - Started process 1142 to run task
[2024-09-05T18:19:15.121+0000] {standard_task_runner.py:105} INFO - Job 112: Subtask get_municipios
[2024-09-05T18:19:15.830+0000] {task_command.py:467} INFO - Running <TaskInstance: weather_etl_dag.get_municipios scheduled__2024-08-19T00:00:00+00:00 [running]> on host 0b8eaea5e88c
[2024-09-05T18:19:16.167+0000] {taskinstance.py:3122} INFO - Exporting env vars: AIRFLOW_CTX_DAG_OWNER='***' AIRFLOW_CTX_DAG_ID='weather_etl_dag' AIRFLOW_CTX_TASK_ID='get_municipios' AIRFLOW_CTX_EXECUTION_DATE='2024-08-19T00:00:00+00:00' AIRFLOW_CTX_TRY_NUMBER='1' AIRFLOW_CTX_DAG_RUN_ID='scheduled__2024-08-19T00:00:00+00:00'
[2024-09-05T18:19:16.170+0000] {taskinstance.py:731} INFO - ::endgroup::
[2024-09-05T18:19:16.727+0000] {logging_mixin.py:190} INFO - Conexi√≥n establecida con Redshift.
[2024-09-05T18:19:16.728+0000] {logging_mixin.py:190} INFO - Ejecutando la consulta SQL...
[2024-09-05T18:19:16.734+0000] {warnings.py:112} WARNING - /root/***/dags/weather_etl.py:29: UserWarning: pandas only supports SQLAlchemy connectable (engine/connection) or database string URI or sqlite3 DBAPI2 connection. Other DBAPI2 objects are not tested. Please consider using SQLAlchemy.
  df_municipios = pd.read_sql_query(query, conn)

[2024-09-05T18:19:16.872+0000] {logging_mixin.py:190} INFO - Consulta ejecutada, n√∫mero de registros obtenidos: 18
[2024-09-05T18:19:16.874+0000] {logging_mixin.py:190} INFO - Conexi√≥n a Redshift cerrada
[2024-09-05T18:19:17.068+0000] {python.py:240} INFO - Done. Returned value was: None
[2024-09-05T18:19:17.082+0000] {taskinstance.py:340} INFO - ::group::Post task execution logs
[2024-09-05T18:19:17.083+0000] {taskinstance.py:352} INFO - Marking task as SUCCESS. dag_id=weather_etl_dag, task_id=get_municipios, run_id=scheduled__2024-08-19T00:00:00+00:00, execution_date=20240819T000000, start_date=20240905T181914, end_date=20240905T181917
[2024-09-05T18:19:17.182+0000] {local_task_job_runner.py:261} INFO - Task exited with return code 0
[2024-09-05T18:19:17.220+0000] {taskinstance.py:3891} INFO - 1 downstream tasks scheduled from follow-on schedule check
[2024-09-05T18:19:17.270+0000] {local_task_job_runner.py:240} INFO - ::endgroup::
